No error handlers are registered, logging exception.
Traceback (most recent call last):
  File "/Users/admin/tears/code/.venv/lib/python3.13/site-packages/telegram/ext/_utils/networkloop.py", line 115, in network_retry_loop
    if not await do_action():
           ^^^^^^^^^^^^^^^^^
  File "/Users/admin/tears/code/.venv/lib/python3.13/site-packages/telegram/ext/_utils/networkloop.py", line 108, in do_action
    return action_cb_task.result()
           ~~~~~~~~~~~~~~~~~~~~~^^
  File "/Users/admin/tears/code/.venv/lib/python3.13/site-packages/telegram/ext/_updater.py", line 376, in polling_action_cb
    updates = await self.bot.get_updates(
              ^^^^^^^^^^^^^^^^^^^^^^^^^^^
    ...<7 lines>...
    )
    ^
  File "/Users/admin/tears/code/.venv/lib/python3.13/site-packages/telegram/ext/_extbot.py", line 658, in get_updates
    updates = await super().get_updates(
              ^^^^^^^^^^^^^^^^^^^^^^^^^^
    ...<9 lines>...
    )
    ^
  File "/Users/admin/tears/code/.venv/lib/python3.13/site-packages/telegram/_bot.py", line 4605, in get_updates
    await self._post(
    ^^^^^^^^^^^^^^^^^
    ...<7 lines>...
    ),
    ^
  File "/Users/admin/tears/code/.venv/lib/python3.13/site-packages/telegram/_bot.py", line 691, in _post
    return await self._do_post(
           ^^^^^^^^^^^^^^^^^^^^
    ...<6 lines>...
    )
    ^
  File "/Users/admin/tears/code/.venv/lib/python3.13/site-packages/telegram/ext/_extbot.py", line 362, in _do_post
    return await super()._do_post(
           ^^^^^^^^^^^^^^^^^^^^^^^
    ...<6 lines>...
    )
    ^
  File "/Users/admin/tears/code/.venv/lib/python3.13/site-packages/telegram/_bot.py", line 720, in _do_post
    result = await request.post(
             ^^^^^^^^^^^^^^^^^^^
    ...<6 lines>...
    )
    ^
  File "/Users/admin/tears/code/.venv/lib/python3.13/site-packages/telegram/request/_baserequest.py", line 202, in post
    result = await self._request_wrapper(
             ^^^^^^^^^^^^^^^^^^^^^^^^^^^^
    ...<7 lines>...
    )
    ^
  File "/Users/admin/tears/code/.venv/lib/python3.13/site-packages/telegram/request/_baserequest.py", line 385, in _request_wrapper
    raise Conflict(message)
telegram.error.Conflict: Conflict: terminated by other getUpdates request; make sure that only one bot instance is running
No error handlers are registered, logging exception.
Traceback (most recent call last):
  File "/Users/admin/tears/code/.venv/lib/python3.13/site-packages/telegram/ext/_utils/networkloop.py", line 115, in network_retry_loop
    if not await do_action():
           ^^^^^^^^^^^^^^^^^
  File "/Users/admin/tears/code/.venv/lib/python3.13/site-packages/telegram/ext/_utils/networkloop.py", line 108, in do_action
    return action_cb_task.result()
           ~~~~~~~~~~~~~~~~~~~~~^^
  File "/Users/admin/tears/code/.venv/lib/python3.13/site-packages/telegram/ext/_updater.py", line 376, in polling_action_cb
    updates = await self.bot.get_updates(
              ^^^^^^^^^^^^^^^^^^^^^^^^^^^
    ...<7 lines>...
    )
    ^
  File "/Users/admin/tears/code/.venv/lib/python3.13/site-packages/telegram/ext/_extbot.py", line 658, in get_updates
    updates = await super().get_updates(
              ^^^^^^^^^^^^^^^^^^^^^^^^^^
    ...<9 lines>...
    )
    ^
  File "/Users/admin/tears/code/.venv/lib/python3.13/site-packages/telegram/_bot.py", line 4605, in get_updates
    await self._post(
    ^^^^^^^^^^^^^^^^^
    ...<7 lines>...
    ),
    ^
  File "/Users/admin/tears/code/.venv/lib/python3.13/site-packages/telegram/_bot.py", line 691, in _post
    return await self._do_post(
           ^^^^^^^^^^^^^^^^^^^^
    ...<6 lines>...
    )
    ^
  File "/Users/admin/tears/code/.venv/lib/python3.13/site-packages/telegram/ext/_extbot.py", line 362, in _do_post
    return await super()._do_post(
           ^^^^^^^^^^^^^^^^^^^^^^^
    ...<6 lines>...
    )
    ^
  File "/Users/admin/tears/code/.venv/lib/python3.13/site-packages/telegram/_bot.py", line 720, in _do_post
    result = await request.post(
             ^^^^^^^^^^^^^^^^^^^
    ...<6 lines>...
    )
    ^
  File "/Users/admin/tears/code/.venv/lib/python3.13/site-packages/telegram/request/_baserequest.py", line 202, in post
    result = await self._request_wrapper(
             ^^^^^^^^^^^^^^^^^^^^^^^^^^^^
    ...<7 lines>...
    )
    ^
  File "/Users/admin/tears/code/.venv/lib/python3.13/site-packages/telegram/request/_baserequest.py", line 385, in _request_wrapper
    raise Conflict(message)
telegram.error.Conflict: Conflict: terminated by other getUpdates request; make sure that only one bot instance is running
No error handlers are registered, logging exception.
Traceback (most recent call last):
  File "/Users/admin/tears/code/.venv/lib/python3.13/site-packages/telegram/ext/_utils/networkloop.py", line 115, in network_retry_loop
    if not await do_action():
           ^^^^^^^^^^^^^^^^^
  File "/Users/admin/tears/code/.venv/lib/python3.13/site-packages/telegram/ext/_utils/networkloop.py", line 108, in do_action
    return action_cb_task.result()
           ~~~~~~~~~~~~~~~~~~~~~^^
  File "/Users/admin/tears/code/.venv/lib/python3.13/site-packages/telegram/ext/_updater.py", line 376, in polling_action_cb
    updates = await self.bot.get_updates(
              ^^^^^^^^^^^^^^^^^^^^^^^^^^^
    ...<7 lines>...
    )
    ^
  File "/Users/admin/tears/code/.venv/lib/python3.13/site-packages/telegram/ext/_extbot.py", line 658, in get_updates
    updates = await super().get_updates(
              ^^^^^^^^^^^^^^^^^^^^^^^^^^
    ...<9 lines>...
    )
    ^
  File "/Users/admin/tears/code/.venv/lib/python3.13/site-packages/telegram/_bot.py", line 4605, in get_updates
    await self._post(
    ^^^^^^^^^^^^^^^^^
    ...<7 lines>...
    ),
    ^
  File "/Users/admin/tears/code/.venv/lib/python3.13/site-packages/telegram/_bot.py", line 691, in _post
    return await self._do_post(
           ^^^^^^^^^^^^^^^^^^^^
    ...<6 lines>...
    )
    ^
  File "/Users/admin/tears/code/.venv/lib/python3.13/site-packages/telegram/ext/_extbot.py", line 362, in _do_post
    return await super()._do_post(
           ^^^^^^^^^^^^^^^^^^^^^^^
    ...<6 lines>...
    )
    ^
  File "/Users/admin/tears/code/.venv/lib/python3.13/site-packages/telegram/_bot.py", line 720, in _do_post
    result = await request.post(
             ^^^^^^^^^^^^^^^^^^^
    ...<6 lines>...
    )
    ^
  File "/Users/admin/tears/code/.venv/lib/python3.13/site-packages/telegram/request/_baserequest.py", line 202, in post
    result = await self._request_wrapper(
             ^^^^^^^^^^^^^^^^^^^^^^^^^^^^
    ...<7 lines>...
    )
    ^
  File "/Users/admin/tears/code/.venv/lib/python3.13/site-packages/telegram/request/_baserequest.py", line 385, in _request_wrapper
    raise Conflict(message)
telegram.error.Conflict: Conflict: terminated by other getUpdates request; make sure that only one bot instance is running
No error handlers are registered, logging exception.
Traceback (most recent call last):
  File "/Users/admin/tears/code/.venv/lib/python3.13/site-packages/telegram/ext/_utils/networkloop.py", line 115, in network_retry_loop
    if not await do_action():
           ^^^^^^^^^^^^^^^^^
  File "/Users/admin/tears/code/.venv/lib/python3.13/site-packages/telegram/ext/_utils/networkloop.py", line 108, in do_action
    return action_cb_task.result()
           ~~~~~~~~~~~~~~~~~~~~~^^
  File "/Users/admin/tears/code/.venv/lib/python3.13/site-packages/telegram/ext/_updater.py", line 376, in polling_action_cb
    updates = await self.bot.get_updates(
              ^^^^^^^^^^^^^^^^^^^^^^^^^^^
    ...<7 lines>...
    )
    ^
  File "/Users/admin/tears/code/.venv/lib/python3.13/site-packages/telegram/ext/_extbot.py", line 658, in get_updates
    updates = await super().get_updates(
              ^^^^^^^^^^^^^^^^^^^^^^^^^^
    ...<9 lines>...
    )
    ^
  File "/Users/admin/tears/code/.venv/lib/python3.13/site-packages/telegram/_bot.py", line 4605, in get_updates
    await self._post(
    ^^^^^^^^^^^^^^^^^
    ...<7 lines>...
    ),
    ^
  File "/Users/admin/tears/code/.venv/lib/python3.13/site-packages/telegram/_bot.py", line 691, in _post
    return await self._do_post(
           ^^^^^^^^^^^^^^^^^^^^
    ...<6 lines>...
    )
    ^
  File "/Users/admin/tears/code/.venv/lib/python3.13/site-packages/telegram/ext/_extbot.py", line 362, in _do_post
    return await super()._do_post(
           ^^^^^^^^^^^^^^^^^^^^^^^
    ...<6 lines>...
    )
    ^
  File "/Users/admin/tears/code/.venv/lib/python3.13/site-packages/telegram/_bot.py", line 720, in _do_post
    result = await request.post(
             ^^^^^^^^^^^^^^^^^^^
    ...<6 lines>...
    )
    ^
  File "/Users/admin/tears/code/.venv/lib/python3.13/site-packages/telegram/request/_baserequest.py", line 202, in post
    result = await self._request_wrapper(
             ^^^^^^^^^^^^^^^^^^^^^^^^^^^^
    ...<7 lines>...
    )
    ^
  File "/Users/admin/tears/code/.venv/lib/python3.13/site-packages/telegram/request/_baserequest.py", line 385, in _request_wrapper
    raise Conflict(message)
telegram.error.Conflict: Conflict: terminated by other getUpdates request; make sure that only one bot instance is running
No error handlers are registered, logging exception.
Traceback (most recent call last):
  File "/Users/admin/tears/code/.venv/lib/python3.13/site-packages/telegram/ext/_utils/networkloop.py", line 115, in network_retry_loop
    if not await do_action():
           ^^^^^^^^^^^^^^^^^
  File "/Users/admin/tears/code/.venv/lib/python3.13/site-packages/telegram/ext/_utils/networkloop.py", line 108, in do_action
    return action_cb_task.result()
           ~~~~~~~~~~~~~~~~~~~~~^^
  File "/Users/admin/tears/code/.venv/lib/python3.13/site-packages/telegram/ext/_updater.py", line 376, in polling_action_cb
    updates = await self.bot.get_updates(
              ^^^^^^^^^^^^^^^^^^^^^^^^^^^
    ...<7 lines>...
    )
    ^
  File "/Users/admin/tears/code/.venv/lib/python3.13/site-packages/telegram/ext/_extbot.py", line 658, in get_updates
    updates = await super().get_updates(
              ^^^^^^^^^^^^^^^^^^^^^^^^^^
    ...<9 lines>...
    )
    ^
  File "/Users/admin/tears/code/.venv/lib/python3.13/site-packages/telegram/_bot.py", line 4605, in get_updates
    await self._post(
    ^^^^^^^^^^^^^^^^^
    ...<7 lines>...
    ),
    ^
  File "/Users/admin/tears/code/.venv/lib/python3.13/site-packages/telegram/_bot.py", line 691, in _post
    return await self._do_post(
           ^^^^^^^^^^^^^^^^^^^^
    ...<6 lines>...
    )
    ^
  File "/Users/admin/tears/code/.venv/lib/python3.13/site-packages/telegram/ext/_extbot.py", line 362, in _do_post
    return await super()._do_post(
           ^^^^^^^^^^^^^^^^^^^^^^^
    ...<6 lines>...
    )
    ^
  File "/Users/admin/tears/code/.venv/lib/python3.13/site-packages/telegram/_bot.py", line 720, in _do_post
    result = await request.post(
             ^^^^^^^^^^^^^^^^^^^
    ...<6 lines>...
    )
    ^
  File "/Users/admin/tears/code/.venv/lib/python3.13/site-packages/telegram/request/_baserequest.py", line 202, in post
    result = await self._request_wrapper(
             ^^^^^^^^^^^^^^^^^^^^^^^^^^^^
    ...<7 lines>...
    )
    ^
  File "/Users/admin/tears/code/.venv/lib/python3.13/site-packages/telegram/request/_baserequest.py", line 385, in _request_wrapper
    raise Conflict(message)
telegram.error.Conflict: Conflict: terminated by other getUpdates request; make sure that only one bot instance is running
No error handlers are registered, logging exception.
Traceback (most recent call last):
  File "/Users/admin/tears/code/.venv/lib/python3.13/site-packages/telegram/ext/_utils/networkloop.py", line 115, in network_retry_loop
    if not await do_action():
           ^^^^^^^^^^^^^^^^^
  File "/Users/admin/tears/code/.venv/lib/python3.13/site-packages/telegram/ext/_utils/networkloop.py", line 108, in do_action
    return action_cb_task.result()
           ~~~~~~~~~~~~~~~~~~~~~^^
  File "/Users/admin/tears/code/.venv/lib/python3.13/site-packages/telegram/ext/_updater.py", line 376, in polling_action_cb
    updates = await self.bot.get_updates(
              ^^^^^^^^^^^^^^^^^^^^^^^^^^^
    ...<7 lines>...
    )
    ^
  File "/Users/admin/tears/code/.venv/lib/python3.13/site-packages/telegram/ext/_extbot.py", line 658, in get_updates
    updates = await super().get_updates(
              ^^^^^^^^^^^^^^^^^^^^^^^^^^
    ...<9 lines>...
    )
    ^
  File "/Users/admin/tears/code/.venv/lib/python3.13/site-packages/telegram/_bot.py", line 4605, in get_updates
    await self._post(
    ^^^^^^^^^^^^^^^^^
    ...<7 lines>...
    ),
    ^
  File "/Users/admin/tears/code/.venv/lib/python3.13/site-packages/telegram/_bot.py", line 691, in _post
    return await self._do_post(
           ^^^^^^^^^^^^^^^^^^^^
    ...<6 lines>...
    )
    ^
  File "/Users/admin/tears/code/.venv/lib/python3.13/site-packages/telegram/ext/_extbot.py", line 362, in _do_post
    return await super()._do_post(
           ^^^^^^^^^^^^^^^^^^^^^^^
    ...<6 lines>...
    )
    ^
  File "/Users/admin/tears/code/.venv/lib/python3.13/site-packages/telegram/_bot.py", line 720, in _do_post
    result = await request.post(
             ^^^^^^^^^^^^^^^^^^^
    ...<6 lines>...
    )
    ^
  File "/Users/admin/tears/code/.venv/lib/python3.13/site-packages/telegram/request/_baserequest.py", line 202, in post
    result = await self._request_wrapper(
             ^^^^^^^^^^^^^^^^^^^^^^^^^^^^
    ...<7 lines>...
    )
    ^
  File "/Users/admin/tears/code/.venv/lib/python3.13/site-packages/telegram/request/_baserequest.py", line 385, in _request_wrapper
    raise Conflict(message)
telegram.error.Conflict: Conflict: terminated by other getUpdates request; make sure that only one bot instance is running
No error handlers are registered, logging exception.
Traceback (most recent call last):
  File "/Users/admin/tears/code/.venv/lib/python3.13/site-packages/telegram/ext/_utils/networkloop.py", line 115, in network_retry_loop
    if not await do_action():
           ^^^^^^^^^^^^^^^^^
  File "/Users/admin/tears/code/.venv/lib/python3.13/site-packages/telegram/ext/_utils/networkloop.py", line 108, in do_action
    return action_cb_task.result()
           ~~~~~~~~~~~~~~~~~~~~~^^
  File "/Users/admin/tears/code/.venv/lib/python3.13/site-packages/telegram/ext/_updater.py", line 376, in polling_action_cb
    updates = await self.bot.get_updates(
              ^^^^^^^^^^^^^^^^^^^^^^^^^^^
    ...<7 lines>...
    )
    ^
  File "/Users/admin/tears/code/.venv/lib/python3.13/site-packages/telegram/ext/_extbot.py", line 658, in get_updates
    updates = await super().get_updates(
              ^^^^^^^^^^^^^^^^^^^^^^^^^^
    ...<9 lines>...
    )
    ^
  File "/Users/admin/tears/code/.venv/lib/python3.13/site-packages/telegram/_bot.py", line 4605, in get_updates
    await self._post(
    ^^^^^^^^^^^^^^^^^
    ...<7 lines>...
    ),
    ^
  File "/Users/admin/tears/code/.venv/lib/python3.13/site-packages/telegram/_bot.py", line 691, in _post
    return await self._do_post(
           ^^^^^^^^^^^^^^^^^^^^
    ...<6 lines>...
    )
    ^
  File "/Users/admin/tears/code/.venv/lib/python3.13/site-packages/telegram/ext/_extbot.py", line 362, in _do_post
    return await super()._do_post(
           ^^^^^^^^^^^^^^^^^^^^^^^
    ...<6 lines>...
    )
    ^
  File "/Users/admin/tears/code/.venv/lib/python3.13/site-packages/telegram/_bot.py", line 720, in _do_post
    result = await request.post(
             ^^^^^^^^^^^^^^^^^^^
    ...<6 lines>...
    )
    ^
  File "/Users/admin/tears/code/.venv/lib/python3.13/site-packages/telegram/request/_baserequest.py", line 202, in post
    result = await self._request_wrapper(
             ^^^^^^^^^^^^^^^^^^^^^^^^^^^^
    ...<7 lines>...
    )
    ^
  File "/Users/admin/tears/code/.venv/lib/python3.13/site-packages/telegram/request/_baserequest.py", line 385, in _request_wrapper
    raise Conflict(message)
telegram.error.Conflict: Conflict: terminated by other getUpdates request; make sure that only one bot instance is running
No error handlers are registered, logging exception.
Traceback (most recent call last):
  File "/Users/admin/tears/code/.venv/lib/python3.13/site-packages/telegram/ext/_utils/networkloop.py", line 115, in network_retry_loop
    if not await do_action():
           ^^^^^^^^^^^^^^^^^
  File "/Users/admin/tears/code/.venv/lib/python3.13/site-packages/telegram/ext/_utils/networkloop.py", line 108, in do_action
    return action_cb_task.result()
           ~~~~~~~~~~~~~~~~~~~~~^^
  File "/Users/admin/tears/code/.venv/lib/python3.13/site-packages/telegram/ext/_updater.py", line 376, in polling_action_cb
    updates = await self.bot.get_updates(
              ^^^^^^^^^^^^^^^^^^^^^^^^^^^
    ...<7 lines>...
    )
    ^
  File "/Users/admin/tears/code/.venv/lib/python3.13/site-packages/telegram/ext/_extbot.py", line 658, in get_updates
    updates = await super().get_updates(
              ^^^^^^^^^^^^^^^^^^^^^^^^^^
    ...<9 lines>...
    )
    ^
  File "/Users/admin/tears/code/.venv/lib/python3.13/site-packages/telegram/_bot.py", line 4605, in get_updates
    await self._post(
    ^^^^^^^^^^^^^^^^^
    ...<7 lines>...
    ),
    ^
  File "/Users/admin/tears/code/.venv/lib/python3.13/site-packages/telegram/_bot.py", line 691, in _post
    return await self._do_post(
           ^^^^^^^^^^^^^^^^^^^^
    ...<6 lines>...
    )
    ^
  File "/Users/admin/tears/code/.venv/lib/python3.13/site-packages/telegram/ext/_extbot.py", line 362, in _do_post
    return await super()._do_post(
           ^^^^^^^^^^^^^^^^^^^^^^^
    ...<6 lines>...
    )
    ^
  File "/Users/admin/tears/code/.venv/lib/python3.13/site-packages/telegram/_bot.py", line 720, in _do_post
    result = await request.post(
             ^^^^^^^^^^^^^^^^^^^
    ...<6 lines>...
    )
    ^
  File "/Users/admin/tears/code/.venv/lib/python3.13/site-packages/telegram/request/_baserequest.py", line 202, in post
    result = await self._request_wrapper(
             ^^^^^^^^^^^^^^^^^^^^^^^^^^^^
    ...<7 lines>...
    )
    ^
  File "/Users/admin/tears/code/.venv/lib/python3.13/site-packages/telegram/request/_baserequest.py", line 385, in _request_wrapper
    raise Conflict(message)
telegram.error.Conflict: Conflict: terminated by other getUpdates request; make sure that only one bot instance is running
No error handlers are registered, logging exception.
Traceback (most recent call last):
  File "/Users/admin/tears/code/.venv/lib/python3.13/site-packages/telegram/ext/_utils/networkloop.py", line 115, in network_retry_loop
    if not await do_action():
           ^^^^^^^^^^^^^^^^^
  File "/Users/admin/tears/code/.venv/lib/python3.13/site-packages/telegram/ext/_utils/networkloop.py", line 108, in do_action
    return action_cb_task.result()
           ~~~~~~~~~~~~~~~~~~~~~^^
  File "/Users/admin/tears/code/.venv/lib/python3.13/site-packages/telegram/ext/_updater.py", line 376, in polling_action_cb
    updates = await self.bot.get_updates(
              ^^^^^^^^^^^^^^^^^^^^^^^^^^^
    ...<7 lines>...
    )
    ^
  File "/Users/admin/tears/code/.venv/lib/python3.13/site-packages/telegram/ext/_extbot.py", line 658, in get_updates
    updates = await super().get_updates(
              ^^^^^^^^^^^^^^^^^^^^^^^^^^
    ...<9 lines>...
    )
    ^
  File "/Users/admin/tears/code/.venv/lib/python3.13/site-packages/telegram/_bot.py", line 4605, in get_updates
    await self._post(
    ^^^^^^^^^^^^^^^^^
    ...<7 lines>...
    ),
    ^
  File "/Users/admin/tears/code/.venv/lib/python3.13/site-packages/telegram/_bot.py", line 691, in _post
    return await self._do_post(
           ^^^^^^^^^^^^^^^^^^^^
    ...<6 lines>...
    )
    ^
  File "/Users/admin/tears/code/.venv/lib/python3.13/site-packages/telegram/ext/_extbot.py", line 362, in _do_post
    return await super()._do_post(
           ^^^^^^^^^^^^^^^^^^^^^^^
    ...<6 lines>...
    )
    ^
  File "/Users/admin/tears/code/.venv/lib/python3.13/site-packages/telegram/_bot.py", line 720, in _do_post
    result = await request.post(
             ^^^^^^^^^^^^^^^^^^^
    ...<6 lines>...
    )
    ^
  File "/Users/admin/tears/code/.venv/lib/python3.13/site-packages/telegram/request/_baserequest.py", line 202, in post
    result = await self._request_wrapper(
             ^^^^^^^^^^^^^^^^^^^^^^^^^^^^
    ...<7 lines>...
    )
    ^
  File "/Users/admin/tears/code/.venv/lib/python3.13/site-packages/telegram/request/_baserequest.py", line 385, in _request_wrapper
    raise Conflict(message)
telegram.error.Conflict: Conflict: terminated by other getUpdates request; make sure that only one bot instance is running
No error handlers are registered, logging exception.
Traceback (most recent call last):
  File "/Users/admin/tears/code/.venv/lib/python3.13/site-packages/telegram/ext/_utils/networkloop.py", line 115, in network_retry_loop
    if not await do_action():
           ^^^^^^^^^^^^^^^^^
  File "/Users/admin/tears/code/.venv/lib/python3.13/site-packages/telegram/ext/_utils/networkloop.py", line 108, in do_action
    return action_cb_task.result()
           ~~~~~~~~~~~~~~~~~~~~~^^
  File "/Users/admin/tears/code/.venv/lib/python3.13/site-packages/telegram/ext/_updater.py", line 376, in polling_action_cb
    updates = await self.bot.get_updates(
              ^^^^^^^^^^^^^^^^^^^^^^^^^^^
    ...<7 lines>...
    )
    ^
  File "/Users/admin/tears/code/.venv/lib/python3.13/site-packages/telegram/ext/_extbot.py", line 658, in get_updates
    updates = await super().get_updates(
              ^^^^^^^^^^^^^^^^^^^^^^^^^^
    ...<9 lines>...
    )
    ^
  File "/Users/admin/tears/code/.venv/lib/python3.13/site-packages/telegram/_bot.py", line 4605, in get_updates
    await self._post(
    ^^^^^^^^^^^^^^^^^
    ...<7 lines>...
    ),
    ^
  File "/Users/admin/tears/code/.venv/lib/python3.13/site-packages/telegram/_bot.py", line 691, in _post
    return await self._do_post(
           ^^^^^^^^^^^^^^^^^^^^
    ...<6 lines>...
    )
    ^
  File "/Users/admin/tears/code/.venv/lib/python3.13/site-packages/telegram/ext/_extbot.py", line 362, in _do_post
    return await super()._do_post(
           ^^^^^^^^^^^^^^^^^^^^^^^
    ...<6 lines>...
    )
    ^
  File "/Users/admin/tears/code/.venv/lib/python3.13/site-packages/telegram/_bot.py", line 720, in _do_post
    result = await request.post(
             ^^^^^^^^^^^^^^^^^^^
    ...<6 lines>...
    )
    ^
  File "/Users/admin/tears/code/.venv/lib/python3.13/site-packages/telegram/request/_baserequest.py", line 202, in post
    result = await self._request_wrapper(
             ^^^^^^^^^^^^^^^^^^^^^^^^^^^^
    ...<7 lines>...
    )
    ^
  File "/Users/admin/tears/code/.venv/lib/python3.13/site-packages/telegram/request/_baserequest.py", line 385, in _request_wrapper
    raise Conflict(message)
telegram.error.Conflict: Conflict: terminated by other getUpdates request; make sure that only one bot instance is running
No error handlers are registered, logging exception.
Traceback (most recent call last):
  File "/Users/admin/tears/code/.venv/lib/python3.13/site-packages/telegram/ext/_utils/networkloop.py", line 115, in network_retry_loop
    if not await do_action():
           ^^^^^^^^^^^^^^^^^
  File "/Users/admin/tears/code/.venv/lib/python3.13/site-packages/telegram/ext/_utils/networkloop.py", line 108, in do_action
    return action_cb_task.result()
           ~~~~~~~~~~~~~~~~~~~~~^^
  File "/Users/admin/tears/code/.venv/lib/python3.13/site-packages/telegram/ext/_updater.py", line 376, in polling_action_cb
    updates = await self.bot.get_updates(
              ^^^^^^^^^^^^^^^^^^^^^^^^^^^
    ...<7 lines>...
    )
    ^
  File "/Users/admin/tears/code/.venv/lib/python3.13/site-packages/telegram/ext/_extbot.py", line 658, in get_updates
    updates = await super().get_updates(
              ^^^^^^^^^^^^^^^^^^^^^^^^^^
    ...<9 lines>...
    )
    ^
  File "/Users/admin/tears/code/.venv/lib/python3.13/site-packages/telegram/_bot.py", line 4605, in get_updates
    await self._post(
    ^^^^^^^^^^^^^^^^^
    ...<7 lines>...
    ),
    ^
  File "/Users/admin/tears/code/.venv/lib/python3.13/site-packages/telegram/_bot.py", line 691, in _post
    return await self._do_post(
           ^^^^^^^^^^^^^^^^^^^^
    ...<6 lines>...
    )
    ^
  File "/Users/admin/tears/code/.venv/lib/python3.13/site-packages/telegram/ext/_extbot.py", line 362, in _do_post
    return await super()._do_post(
           ^^^^^^^^^^^^^^^^^^^^^^^
    ...<6 lines>...
    )
    ^
  File "/Users/admin/tears/code/.venv/lib/python3.13/site-packages/telegram/_bot.py", line 720, in _do_post
    result = await request.post(
             ^^^^^^^^^^^^^^^^^^^
    ...<6 lines>...
    )
    ^
  File "/Users/admin/tears/code/.venv/lib/python3.13/site-packages/telegram/request/_baserequest.py", line 202, in post
    result = await self._request_wrapper(
             ^^^^^^^^^^^^^^^^^^^^^^^^^^^^
    ...<7 lines>...
    )
    ^
  File "/Users/admin/tears/code/.venv/lib/python3.13/site-packages/telegram/request/_baserequest.py", line 385, in _request_wrapper
    raise Conflict(message)
telegram.error.Conflict: Conflict: terminated by other getUpdates request; make sure that only one bot instance is running
No error handlers are registered, logging exception.
Traceback (most recent call last):
  File "/Users/admin/tears/code/.venv/lib/python3.13/site-packages/telegram/ext/_utils/networkloop.py", line 115, in network_retry_loop
    if not await do_action():
           ^^^^^^^^^^^^^^^^^
  File "/Users/admin/tears/code/.venv/lib/python3.13/site-packages/telegram/ext/_utils/networkloop.py", line 108, in do_action
    return action_cb_task.result()
           ~~~~~~~~~~~~~~~~~~~~~^^
  File "/Users/admin/tears/code/.venv/lib/python3.13/site-packages/telegram/ext/_updater.py", line 376, in polling_action_cb
    updates = await self.bot.get_updates(
              ^^^^^^^^^^^^^^^^^^^^^^^^^^^
    ...<7 lines>...
    )
    ^
  File "/Users/admin/tears/code/.venv/lib/python3.13/site-packages/telegram/ext/_extbot.py", line 658, in get_updates
    updates = await super().get_updates(
              ^^^^^^^^^^^^^^^^^^^^^^^^^^
    ...<9 lines>...
    )
    ^
  File "/Users/admin/tears/code/.venv/lib/python3.13/site-packages/telegram/_bot.py", line 4605, in get_updates
    await self._post(
    ^^^^^^^^^^^^^^^^^
    ...<7 lines>...
    ),
    ^
  File "/Users/admin/tears/code/.venv/lib/python3.13/site-packages/telegram/_bot.py", line 691, in _post
    return await self._do_post(
           ^^^^^^^^^^^^^^^^^^^^
    ...<6 lines>...
    )
    ^
  File "/Users/admin/tears/code/.venv/lib/python3.13/site-packages/telegram/ext/_extbot.py", line 362, in _do_post
    return await super()._do_post(
           ^^^^^^^^^^^^^^^^^^^^^^^
    ...<6 lines>...
    )
    ^
  File "/Users/admin/tears/code/.venv/lib/python3.13/site-packages/telegram/_bot.py", line 720, in _do_post
    result = await request.post(
             ^^^^^^^^^^^^^^^^^^^
    ...<6 lines>...
    )
    ^
  File "/Users/admin/tears/code/.venv/lib/python3.13/site-packages/telegram/request/_baserequest.py", line 202, in post
    result = await self._request_wrapper(
             ^^^^^^^^^^^^^^^^^^^^^^^^^^^^
    ...<7 lines>...
    )
    ^
  File "/Users/admin/tears/code/.venv/lib/python3.13/site-packages/telegram/request/_baserequest.py", line 385, in _request_wrapper
    raise Conflict(message)
telegram.error.Conflict: Conflict: terminated by other getUpdates request; make sure that only one bot instance is running
No error handlers are registered, logging exception.
Traceback (most recent call last):
  File "/Users/admin/tears/code/.venv/lib/python3.13/site-packages/telegram/ext/_utils/networkloop.py", line 115, in network_retry_loop
    if not await do_action():
           ^^^^^^^^^^^^^^^^^
  File "/Users/admin/tears/code/.venv/lib/python3.13/site-packages/telegram/ext/_utils/networkloop.py", line 108, in do_action
    return action_cb_task.result()
           ~~~~~~~~~~~~~~~~~~~~~^^
  File "/Users/admin/tears/code/.venv/lib/python3.13/site-packages/telegram/ext/_updater.py", line 376, in polling_action_cb
    updates = await self.bot.get_updates(
              ^^^^^^^^^^^^^^^^^^^^^^^^^^^
    ...<7 lines>...
    )
    ^
  File "/Users/admin/tears/code/.venv/lib/python3.13/site-packages/telegram/ext/_extbot.py", line 658, in get_updates
    updates = await super().get_updates(
              ^^^^^^^^^^^^^^^^^^^^^^^^^^
    ...<9 lines>...
    )
    ^
  File "/Users/admin/tears/code/.venv/lib/python3.13/site-packages/telegram/_bot.py", line 4605, in get_updates
    await self._post(
    ^^^^^^^^^^^^^^^^^
    ...<7 lines>...
    ),
    ^
  File "/Users/admin/tears/code/.venv/lib/python3.13/site-packages/telegram/_bot.py", line 691, in _post
    return await self._do_post(
           ^^^^^^^^^^^^^^^^^^^^
    ...<6 lines>...
    )
    ^
  File "/Users/admin/tears/code/.venv/lib/python3.13/site-packages/telegram/ext/_extbot.py", line 362, in _do_post
    return await super()._do_post(
           ^^^^^^^^^^^^^^^^^^^^^^^
    ...<6 lines>...
    )
    ^
  File "/Users/admin/tears/code/.venv/lib/python3.13/site-packages/telegram/_bot.py", line 720, in _do_post
    result = await request.post(
             ^^^^^^^^^^^^^^^^^^^
    ...<6 lines>...
    )
    ^
  File "/Users/admin/tears/code/.venv/lib/python3.13/site-packages/telegram/request/_baserequest.py", line 202, in post
    result = await self._request_wrapper(
             ^^^^^^^^^^^^^^^^^^^^^^^^^^^^
    ...<7 lines>...
    )
    ^
  File "/Users/admin/tears/code/.venv/lib/python3.13/site-packages/telegram/request/_baserequest.py", line 385, in _request_wrapper
    raise Conflict(message)
telegram.error.Conflict: Conflict: terminated by other getUpdates request; make sure that only one bot instance is running
No error handlers are registered, logging exception.
Traceback (most recent call last):
  File "/Users/admin/tears/code/.venv/lib/python3.13/site-packages/telegram/ext/_utils/networkloop.py", line 115, in network_retry_loop
    if not await do_action():
           ^^^^^^^^^^^^^^^^^
  File "/Users/admin/tears/code/.venv/lib/python3.13/site-packages/telegram/ext/_utils/networkloop.py", line 108, in do_action
    return action_cb_task.result()
           ~~~~~~~~~~~~~~~~~~~~~^^
  File "/Users/admin/tears/code/.venv/lib/python3.13/site-packages/telegram/ext/_updater.py", line 376, in polling_action_cb
    updates = await self.bot.get_updates(
              ^^^^^^^^^^^^^^^^^^^^^^^^^^^
    ...<7 lines>...
    )
    ^
  File "/Users/admin/tears/code/.venv/lib/python3.13/site-packages/telegram/ext/_extbot.py", line 658, in get_updates
    updates = await super().get_updates(
              ^^^^^^^^^^^^^^^^^^^^^^^^^^
    ...<9 lines>...
    )
    ^
  File "/Users/admin/tears/code/.venv/lib/python3.13/site-packages/telegram/_bot.py", line 4605, in get_updates
    await self._post(
    ^^^^^^^^^^^^^^^^^
    ...<7 lines>...
    ),
    ^
  File "/Users/admin/tears/code/.venv/lib/python3.13/site-packages/telegram/_bot.py", line 691, in _post
    return await self._do_post(
           ^^^^^^^^^^^^^^^^^^^^
    ...<6 lines>...
    )
    ^
  File "/Users/admin/tears/code/.venv/lib/python3.13/site-packages/telegram/ext/_extbot.py", line 362, in _do_post
    return await super()._do_post(
           ^^^^^^^^^^^^^^^^^^^^^^^
    ...<6 lines>...
    )
    ^
  File "/Users/admin/tears/code/.venv/lib/python3.13/site-packages/telegram/_bot.py", line 720, in _do_post
    result = await request.post(
             ^^^^^^^^^^^^^^^^^^^
    ...<6 lines>...
    )
    ^
  File "/Users/admin/tears/code/.venv/lib/python3.13/site-packages/telegram/request/_baserequest.py", line 202, in post
    result = await self._request_wrapper(
             ^^^^^^^^^^^^^^^^^^^^^^^^^^^^
    ...<7 lines>...
    )
    ^
  File "/Users/admin/tears/code/.venv/lib/python3.13/site-packages/telegram/request/_baserequest.py", line 385, in _request_wrapper
    raise Conflict(message)
telegram.error.Conflict: Conflict: terminated by other getUpdates request; make sure that only one bot instance is running
No error handlers are registered, logging exception.
Traceback (most recent call last):
  File "/Users/admin/tears/code/.venv/lib/python3.13/site-packages/telegram/ext/_utils/networkloop.py", line 115, in network_retry_loop
    if not await do_action():
           ^^^^^^^^^^^^^^^^^
  File "/Users/admin/tears/code/.venv/lib/python3.13/site-packages/telegram/ext/_utils/networkloop.py", line 108, in do_action
    return action_cb_task.result()
           ~~~~~~~~~~~~~~~~~~~~~^^
  File "/Users/admin/tears/code/.venv/lib/python3.13/site-packages/telegram/ext/_updater.py", line 376, in polling_action_cb
    updates = await self.bot.get_updates(
              ^^^^^^^^^^^^^^^^^^^^^^^^^^^
    ...<7 lines>...
    )
    ^
  File "/Users/admin/tears/code/.venv/lib/python3.13/site-packages/telegram/ext/_extbot.py", line 658, in get_updates
    updates = await super().get_updates(
              ^^^^^^^^^^^^^^^^^^^^^^^^^^
    ...<9 lines>...
    )
    ^
  File "/Users/admin/tears/code/.venv/lib/python3.13/site-packages/telegram/_bot.py", line 4605, in get_updates
    await self._post(
    ^^^^^^^^^^^^^^^^^
    ...<7 lines>...
    ),
    ^
  File "/Users/admin/tears/code/.venv/lib/python3.13/site-packages/telegram/_bot.py", line 691, in _post
    return await self._do_post(
           ^^^^^^^^^^^^^^^^^^^^
    ...<6 lines>...
    )
    ^
  File "/Users/admin/tears/code/.venv/lib/python3.13/site-packages/telegram/ext/_extbot.py", line 362, in _do_post
    return await super()._do_post(
           ^^^^^^^^^^^^^^^^^^^^^^^
    ...<6 lines>...
    )
    ^
  File "/Users/admin/tears/code/.venv/lib/python3.13/site-packages/telegram/_bot.py", line 720, in _do_post
    result = await request.post(
             ^^^^^^^^^^^^^^^^^^^
    ...<6 lines>...
    )
    ^
  File "/Users/admin/tears/code/.venv/lib/python3.13/site-packages/telegram/request/_baserequest.py", line 202, in post
    result = await self._request_wrapper(
             ^^^^^^^^^^^^^^^^^^^^^^^^^^^^
    ...<7 lines>...
    )
    ^
  File "/Users/admin/tears/code/.venv/lib/python3.13/site-packages/telegram/request/_baserequest.py", line 385, in _request_wrapper
    raise Conflict(message)
telegram.error.Conflict: Conflict: terminated by other getUpdates request; make sure that only one bot instance is running
No error handlers are registered, logging exception.
Traceback (most recent call last):
  File "/Users/admin/tears/code/.venv/lib/python3.13/site-packages/telegram/ext/_utils/networkloop.py", line 115, in network_retry_loop
    if not await do_action():
           ^^^^^^^^^^^^^^^^^
  File "/Users/admin/tears/code/.venv/lib/python3.13/site-packages/telegram/ext/_utils/networkloop.py", line 108, in do_action
    return action_cb_task.result()
           ~~~~~~~~~~~~~~~~~~~~~^^
  File "/Users/admin/tears/code/.venv/lib/python3.13/site-packages/telegram/ext/_updater.py", line 376, in polling_action_cb
    updates = await self.bot.get_updates(
              ^^^^^^^^^^^^^^^^^^^^^^^^^^^
    ...<7 lines>...
    )
    ^
  File "/Users/admin/tears/code/.venv/lib/python3.13/site-packages/telegram/ext/_extbot.py", line 658, in get_updates
    updates = await super().get_updates(
              ^^^^^^^^^^^^^^^^^^^^^^^^^^
    ...<9 lines>...
    )
    ^
  File "/Users/admin/tears/code/.venv/lib/python3.13/site-packages/telegram/_bot.py", line 4605, in get_updates
    await self._post(
    ^^^^^^^^^^^^^^^^^
    ...<7 lines>...
    ),
    ^
  File "/Users/admin/tears/code/.venv/lib/python3.13/site-packages/telegram/_bot.py", line 691, in _post
    return await self._do_post(
           ^^^^^^^^^^^^^^^^^^^^
    ...<6 lines>...
    )
    ^
  File "/Users/admin/tears/code/.venv/lib/python3.13/site-packages/telegram/ext/_extbot.py", line 362, in _do_post
    return await super()._do_post(
           ^^^^^^^^^^^^^^^^^^^^^^^
    ...<6 lines>...
    )
    ^
  File "/Users/admin/tears/code/.venv/lib/python3.13/site-packages/telegram/_bot.py", line 720, in _do_post
    result = await request.post(
             ^^^^^^^^^^^^^^^^^^^
    ...<6 lines>...
    )
    ^
  File "/Users/admin/tears/code/.venv/lib/python3.13/site-packages/telegram/request/_baserequest.py", line 202, in post
    result = await self._request_wrapper(
             ^^^^^^^^^^^^^^^^^^^^^^^^^^^^
    ...<7 lines>...
    )
    ^
  File "/Users/admin/tears/code/.venv/lib/python3.13/site-packages/telegram/request/_baserequest.py", line 385, in _request_wrapper
    raise Conflict(message)
telegram.error.Conflict: Conflict: terminated by other getUpdates request; make sure that only one bot instance is running
No error handlers are registered, logging exception.
Traceback (most recent call last):
  File "/Users/admin/tears/code/.venv/lib/python3.13/site-packages/telegram/ext/_utils/networkloop.py", line 115, in network_retry_loop
    if not await do_action():
           ^^^^^^^^^^^^^^^^^
  File "/Users/admin/tears/code/.venv/lib/python3.13/site-packages/telegram/ext/_utils/networkloop.py", line 108, in do_action
    return action_cb_task.result()
           ~~~~~~~~~~~~~~~~~~~~~^^
  File "/Users/admin/tears/code/.venv/lib/python3.13/site-packages/telegram/ext/_updater.py", line 376, in polling_action_cb
    updates = await self.bot.get_updates(
              ^^^^^^^^^^^^^^^^^^^^^^^^^^^
    ...<7 lines>...
    )
    ^
  File "/Users/admin/tears/code/.venv/lib/python3.13/site-packages/telegram/ext/_extbot.py", line 658, in get_updates
    updates = await super().get_updates(
              ^^^^^^^^^^^^^^^^^^^^^^^^^^
    ...<9 lines>...
    )
    ^
  File "/Users/admin/tears/code/.venv/lib/python3.13/site-packages/telegram/_bot.py", line 4605, in get_updates
    await self._post(
    ^^^^^^^^^^^^^^^^^
    ...<7 lines>...
    ),
    ^
  File "/Users/admin/tears/code/.venv/lib/python3.13/site-packages/telegram/_bot.py", line 691, in _post
    return await self._do_post(
           ^^^^^^^^^^^^^^^^^^^^
    ...<6 lines>...
    )
    ^
  File "/Users/admin/tears/code/.venv/lib/python3.13/site-packages/telegram/ext/_extbot.py", line 362, in _do_post
    return await super()._do_post(
           ^^^^^^^^^^^^^^^^^^^^^^^
    ...<6 lines>...
    )
    ^
  File "/Users/admin/tears/code/.venv/lib/python3.13/site-packages/telegram/_bot.py", line 720, in _do_post
    result = await request.post(
             ^^^^^^^^^^^^^^^^^^^
    ...<6 lines>...
    )
    ^
  File "/Users/admin/tears/code/.venv/lib/python3.13/site-packages/telegram/request/_baserequest.py", line 202, in post
    result = await self._request_wrapper(
             ^^^^^^^^^^^^^^^^^^^^^^^^^^^^
    ...<7 lines>...
    )
    ^
  File "/Users/admin/tears/code/.venv/lib/python3.13/site-packages/telegram/request/_baserequest.py", line 385, in _request_wrapper
    raise Conflict(message)
telegram.error.Conflict: Conflict: terminated by other getUpdates request; make sure that only one bot instance is running
No error handlers are registered, logging exception.
Traceback (most recent call last):
  File "/Users/admin/tears/code/.venv/lib/python3.13/site-packages/telegram/ext/_utils/networkloop.py", line 115, in network_retry_loop
    if not await do_action():
           ^^^^^^^^^^^^^^^^^
  File "/Users/admin/tears/code/.venv/lib/python3.13/site-packages/telegram/ext/_utils/networkloop.py", line 108, in do_action
    return action_cb_task.result()
           ~~~~~~~~~~~~~~~~~~~~~^^
  File "/Users/admin/tears/code/.venv/lib/python3.13/site-packages/telegram/ext/_updater.py", line 376, in polling_action_cb
    updates = await self.bot.get_updates(
              ^^^^^^^^^^^^^^^^^^^^^^^^^^^
    ...<7 lines>...
    )
    ^
  File "/Users/admin/tears/code/.venv/lib/python3.13/site-packages/telegram/ext/_extbot.py", line 658, in get_updates
    updates = await super().get_updates(
              ^^^^^^^^^^^^^^^^^^^^^^^^^^
    ...<9 lines>...
    )
    ^
  File "/Users/admin/tears/code/.venv/lib/python3.13/site-packages/telegram/_bot.py", line 4605, in get_updates
    await self._post(
    ^^^^^^^^^^^^^^^^^
    ...<7 lines>...
    ),
    ^
  File "/Users/admin/tears/code/.venv/lib/python3.13/site-packages/telegram/_bot.py", line 691, in _post
    return await self._do_post(
           ^^^^^^^^^^^^^^^^^^^^
    ...<6 lines>...
    )
    ^
  File "/Users/admin/tears/code/.venv/lib/python3.13/site-packages/telegram/ext/_extbot.py", line 362, in _do_post
    return await super()._do_post(
           ^^^^^^^^^^^^^^^^^^^^^^^
    ...<6 lines>...
    )
    ^
  File "/Users/admin/tears/code/.venv/lib/python3.13/site-packages/telegram/_bot.py", line 720, in _do_post
    result = await request.post(
             ^^^^^^^^^^^^^^^^^^^
    ...<6 lines>...
    )
    ^
  File "/Users/admin/tears/code/.venv/lib/python3.13/site-packages/telegram/request/_baserequest.py", line 202, in post
    result = await self._request_wrapper(
             ^^^^^^^^^^^^^^^^^^^^^^^^^^^^
    ...<7 lines>...
    )
    ^
  File "/Users/admin/tears/code/.venv/lib/python3.13/site-packages/telegram/request/_baserequest.py", line 385, in _request_wrapper
    raise Conflict(message)
telegram.error.Conflict: Conflict: terminated by other getUpdates request; make sure that only one bot instance is running
No error handlers are registered, logging exception.
Traceback (most recent call last):
  File "/Users/admin/tears/code/.venv/lib/python3.13/site-packages/telegram/ext/_utils/networkloop.py", line 115, in network_retry_loop
    if not await do_action():
           ^^^^^^^^^^^^^^^^^
  File "/Users/admin/tears/code/.venv/lib/python3.13/site-packages/telegram/ext/_utils/networkloop.py", line 108, in do_action
    return action_cb_task.result()
           ~~~~~~~~~~~~~~~~~~~~~^^
  File "/Users/admin/tears/code/.venv/lib/python3.13/site-packages/telegram/ext/_updater.py", line 376, in polling_action_cb
    updates = await self.bot.get_updates(
              ^^^^^^^^^^^^^^^^^^^^^^^^^^^
    ...<7 lines>...
    )
    ^
  File "/Users/admin/tears/code/.venv/lib/python3.13/site-packages/telegram/ext/_extbot.py", line 658, in get_updates
    updates = await super().get_updates(
              ^^^^^^^^^^^^^^^^^^^^^^^^^^
    ...<9 lines>...
    )
    ^
  File "/Users/admin/tears/code/.venv/lib/python3.13/site-packages/telegram/_bot.py", line 4605, in get_updates
    await self._post(
    ^^^^^^^^^^^^^^^^^
    ...<7 lines>...
    ),
    ^
  File "/Users/admin/tears/code/.venv/lib/python3.13/site-packages/telegram/_bot.py", line 691, in _post
    return await self._do_post(
           ^^^^^^^^^^^^^^^^^^^^
    ...<6 lines>...
    )
    ^
  File "/Users/admin/tears/code/.venv/lib/python3.13/site-packages/telegram/ext/_extbot.py", line 362, in _do_post
    return await super()._do_post(
           ^^^^^^^^^^^^^^^^^^^^^^^
    ...<6 lines>...
    )
    ^
  File "/Users/admin/tears/code/.venv/lib/python3.13/site-packages/telegram/_bot.py", line 720, in _do_post
    result = await request.post(
             ^^^^^^^^^^^^^^^^^^^
    ...<6 lines>...
    )
    ^
  File "/Users/admin/tears/code/.venv/lib/python3.13/site-packages/telegram/request/_baserequest.py", line 202, in post
    result = await self._request_wrapper(
             ^^^^^^^^^^^^^^^^^^^^^^^^^^^^
    ...<7 lines>...
    )
    ^
  File "/Users/admin/tears/code/.venv/lib/python3.13/site-packages/telegram/request/_baserequest.py", line 385, in _request_wrapper
    raise Conflict(message)
telegram.error.Conflict: Conflict: terminated by other getUpdates request; make sure that only one bot instance is running
No error handlers are registered, logging exception.
Traceback (most recent call last):
  File "/Users/admin/tears/code/.venv/lib/python3.13/site-packages/telegram/ext/_utils/networkloop.py", line 115, in network_retry_loop
    if not await do_action():
           ^^^^^^^^^^^^^^^^^
  File "/Users/admin/tears/code/.venv/lib/python3.13/site-packages/telegram/ext/_utils/networkloop.py", line 108, in do_action
    return action_cb_task.result()
           ~~~~~~~~~~~~~~~~~~~~~^^
  File "/Users/admin/tears/code/.venv/lib/python3.13/site-packages/telegram/ext/_updater.py", line 376, in polling_action_cb
    updates = await self.bot.get_updates(
              ^^^^^^^^^^^^^^^^^^^^^^^^^^^
    ...<7 lines>...
    )
    ^
  File "/Users/admin/tears/code/.venv/lib/python3.13/site-packages/telegram/ext/_extbot.py", line 658, in get_updates
    updates = await super().get_updates(
              ^^^^^^^^^^^^^^^^^^^^^^^^^^
    ...<9 lines>...
    )
    ^
  File "/Users/admin/tears/code/.venv/lib/python3.13/site-packages/telegram/_bot.py", line 4605, in get_updates
    await self._post(
    ^^^^^^^^^^^^^^^^^
    ...<7 lines>...
    ),
    ^
  File "/Users/admin/tears/code/.venv/lib/python3.13/site-packages/telegram/_bot.py", line 691, in _post
    return await self._do_post(
           ^^^^^^^^^^^^^^^^^^^^
    ...<6 lines>...
    )
    ^
  File "/Users/admin/tears/code/.venv/lib/python3.13/site-packages/telegram/ext/_extbot.py", line 362, in _do_post
    return await super()._do_post(
           ^^^^^^^^^^^^^^^^^^^^^^^
    ...<6 lines>...
    )
    ^
  File "/Users/admin/tears/code/.venv/lib/python3.13/site-packages/telegram/_bot.py", line 720, in _do_post
    result = await request.post(
             ^^^^^^^^^^^^^^^^^^^
    ...<6 lines>...
    )
    ^
  File "/Users/admin/tears/code/.venv/lib/python3.13/site-packages/telegram/request/_baserequest.py", line 202, in post
    result = await self._request_wrapper(
             ^^^^^^^^^^^^^^^^^^^^^^^^^^^^
    ...<7 lines>...
    )
    ^
  File "/Users/admin/tears/code/.venv/lib/python3.13/site-packages/telegram/request/_baserequest.py", line 385, in _request_wrapper
    raise Conflict(message)
telegram.error.Conflict: Conflict: terminated by other getUpdates request; make sure that only one bot instance is running
No error handlers are registered, logging exception.
Traceback (most recent call last):
  File "/Users/admin/tears/code/.venv/lib/python3.13/site-packages/telegram/ext/_utils/networkloop.py", line 115, in network_retry_loop
    if not await do_action():
           ^^^^^^^^^^^^^^^^^
  File "/Users/admin/tears/code/.venv/lib/python3.13/site-packages/telegram/ext/_utils/networkloop.py", line 108, in do_action
    return action_cb_task.result()
           ~~~~~~~~~~~~~~~~~~~~~^^
  File "/Users/admin/tears/code/.venv/lib/python3.13/site-packages/telegram/ext/_updater.py", line 376, in polling_action_cb
    updates = await self.bot.get_updates(
              ^^^^^^^^^^^^^^^^^^^^^^^^^^^
    ...<7 lines>...
    )
    ^
  File "/Users/admin/tears/code/.venv/lib/python3.13/site-packages/telegram/ext/_extbot.py", line 658, in get_updates
    updates = await super().get_updates(
              ^^^^^^^^^^^^^^^^^^^^^^^^^^
    ...<9 lines>...
    )
    ^
  File "/Users/admin/tears/code/.venv/lib/python3.13/site-packages/telegram/_bot.py", line 4605, in get_updates
    await self._post(
    ^^^^^^^^^^^^^^^^^
    ...<7 lines>...
    ),
    ^
  File "/Users/admin/tears/code/.venv/lib/python3.13/site-packages/telegram/_bot.py", line 691, in _post
    return await self._do_post(
           ^^^^^^^^^^^^^^^^^^^^
    ...<6 lines>...
    )
    ^
  File "/Users/admin/tears/code/.venv/lib/python3.13/site-packages/telegram/ext/_extbot.py", line 362, in _do_post
    return await super()._do_post(
           ^^^^^^^^^^^^^^^^^^^^^^^
    ...<6 lines>...
    )
    ^
  File "/Users/admin/tears/code/.venv/lib/python3.13/site-packages/telegram/_bot.py", line 720, in _do_post
    result = await request.post(
             ^^^^^^^^^^^^^^^^^^^
    ...<6 lines>...
    )
    ^
  File "/Users/admin/tears/code/.venv/lib/python3.13/site-packages/telegram/request/_baserequest.py", line 202, in post
    result = await self._request_wrapper(
             ^^^^^^^^^^^^^^^^^^^^^^^^^^^^
    ...<7 lines>...
    )
    ^
  File "/Users/admin/tears/code/.venv/lib/python3.13/site-packages/telegram/request/_baserequest.py", line 385, in _request_wrapper
    raise Conflict(message)
telegram.error.Conflict: Conflict: terminated by other getUpdates request; make sure that only one bot instance is running
No error handlers are registered, logging exception.
Traceback (most recent call last):
  File "/Users/admin/tears/code/.venv/lib/python3.13/site-packages/telegram/ext/_utils/networkloop.py", line 115, in network_retry_loop
    if not await do_action():
           ^^^^^^^^^^^^^^^^^
  File "/Users/admin/tears/code/.venv/lib/python3.13/site-packages/telegram/ext/_utils/networkloop.py", line 108, in do_action
    return action_cb_task.result()
           ~~~~~~~~~~~~~~~~~~~~~^^
  File "/Users/admin/tears/code/.venv/lib/python3.13/site-packages/telegram/ext/_updater.py", line 376, in polling_action_cb
    updates = await self.bot.get_updates(
              ^^^^^^^^^^^^^^^^^^^^^^^^^^^
    ...<7 lines>...
    )
    ^
  File "/Users/admin/tears/code/.venv/lib/python3.13/site-packages/telegram/ext/_extbot.py", line 658, in get_updates
    updates = await super().get_updates(
              ^^^^^^^^^^^^^^^^^^^^^^^^^^
    ...<9 lines>...
    )
    ^
  File "/Users/admin/tears/code/.venv/lib/python3.13/site-packages/telegram/_bot.py", line 4605, in get_updates
    await self._post(
    ^^^^^^^^^^^^^^^^^
    ...<7 lines>...
    ),
    ^
  File "/Users/admin/tears/code/.venv/lib/python3.13/site-packages/telegram/_bot.py", line 691, in _post
    return await self._do_post(
           ^^^^^^^^^^^^^^^^^^^^
    ...<6 lines>...
    )
    ^
  File "/Users/admin/tears/code/.venv/lib/python3.13/site-packages/telegram/ext/_extbot.py", line 362, in _do_post
    return await super()._do_post(
           ^^^^^^^^^^^^^^^^^^^^^^^
    ...<6 lines>...
    )
    ^
  File "/Users/admin/tears/code/.venv/lib/python3.13/site-packages/telegram/_bot.py", line 720, in _do_post
    result = await request.post(
             ^^^^^^^^^^^^^^^^^^^
    ...<6 lines>...
    )
    ^
  File "/Users/admin/tears/code/.venv/lib/python3.13/site-packages/telegram/request/_baserequest.py", line 202, in post
    result = await self._request_wrapper(
             ^^^^^^^^^^^^^^^^^^^^^^^^^^^^
    ...<7 lines>...
    )
    ^
  File "/Users/admin/tears/code/.venv/lib/python3.13/site-packages/telegram/request/_baserequest.py", line 385, in _request_wrapper
    raise Conflict(message)
telegram.error.Conflict: Conflict: terminated by other getUpdates request; make sure that only one bot instance is running
No error handlers are registered, logging exception.
Traceback (most recent call last):
  File "/Users/admin/tears/code/.venv/lib/python3.13/site-packages/telegram/ext/_utils/networkloop.py", line 115, in network_retry_loop
    if not await do_action():
           ^^^^^^^^^^^^^^^^^
  File "/Users/admin/tears/code/.venv/lib/python3.13/site-packages/telegram/ext/_utils/networkloop.py", line 108, in do_action
    return action_cb_task.result()
           ~~~~~~~~~~~~~~~~~~~~~^^
  File "/Users/admin/tears/code/.venv/lib/python3.13/site-packages/telegram/ext/_updater.py", line 376, in polling_action_cb
    updates = await self.bot.get_updates(
              ^^^^^^^^^^^^^^^^^^^^^^^^^^^
    ...<7 lines>...
    )
    ^
  File "/Users/admin/tears/code/.venv/lib/python3.13/site-packages/telegram/ext/_extbot.py", line 658, in get_updates
    updates = await super().get_updates(
              ^^^^^^^^^^^^^^^^^^^^^^^^^^
    ...<9 lines>...
    )
    ^
  File "/Users/admin/tears/code/.venv/lib/python3.13/site-packages/telegram/_bot.py", line 4605, in get_updates
    await self._post(
    ^^^^^^^^^^^^^^^^^
    ...<7 lines>...
    ),
    ^
  File "/Users/admin/tears/code/.venv/lib/python3.13/site-packages/telegram/_bot.py", line 691, in _post
    return await self._do_post(
           ^^^^^^^^^^^^^^^^^^^^
    ...<6 lines>...
    )
    ^
  File "/Users/admin/tears/code/.venv/lib/python3.13/site-packages/telegram/ext/_extbot.py", line 362, in _do_post
    return await super()._do_post(
           ^^^^^^^^^^^^^^^^^^^^^^^
    ...<6 lines>...
    )
    ^
  File "/Users/admin/tears/code/.venv/lib/python3.13/site-packages/telegram/_bot.py", line 720, in _do_post
    result = await request.post(
             ^^^^^^^^^^^^^^^^^^^
    ...<6 lines>...
    )
    ^
  File "/Users/admin/tears/code/.venv/lib/python3.13/site-packages/telegram/request/_baserequest.py", line 202, in post
    result = await self._request_wrapper(
             ^^^^^^^^^^^^^^^^^^^^^^^^^^^^
    ...<7 lines>...
    )
    ^
  File "/Users/admin/tears/code/.venv/lib/python3.13/site-packages/telegram/request/_baserequest.py", line 385, in _request_wrapper
    raise Conflict(message)
telegram.error.Conflict: Conflict: terminated by other getUpdates request; make sure that only one bot instance is running
No error handlers are registered, logging exception.
Traceback (most recent call last):
  File "/Users/admin/tears/code/.venv/lib/python3.13/site-packages/telegram/ext/_utils/networkloop.py", line 115, in network_retry_loop
    if not await do_action():
           ^^^^^^^^^^^^^^^^^
  File "/Users/admin/tears/code/.venv/lib/python3.13/site-packages/telegram/ext/_utils/networkloop.py", line 108, in do_action
    return action_cb_task.result()
           ~~~~~~~~~~~~~~~~~~~~~^^
  File "/Users/admin/tears/code/.venv/lib/python3.13/site-packages/telegram/ext/_updater.py", line 376, in polling_action_cb
    updates = await self.bot.get_updates(
              ^^^^^^^^^^^^^^^^^^^^^^^^^^^
    ...<7 lines>...
    )
    ^
  File "/Users/admin/tears/code/.venv/lib/python3.13/site-packages/telegram/ext/_extbot.py", line 658, in get_updates
    updates = await super().get_updates(
              ^^^^^^^^^^^^^^^^^^^^^^^^^^
    ...<9 lines>...
    )
    ^
  File "/Users/admin/tears/code/.venv/lib/python3.13/site-packages/telegram/_bot.py", line 4605, in get_updates
    await self._post(
    ^^^^^^^^^^^^^^^^^
    ...<7 lines>...
    ),
    ^
  File "/Users/admin/tears/code/.venv/lib/python3.13/site-packages/telegram/_bot.py", line 691, in _post
    return await self._do_post(
           ^^^^^^^^^^^^^^^^^^^^
    ...<6 lines>...
    )
    ^
  File "/Users/admin/tears/code/.venv/lib/python3.13/site-packages/telegram/ext/_extbot.py", line 362, in _do_post
    return await super()._do_post(
           ^^^^^^^^^^^^^^^^^^^^^^^
    ...<6 lines>...
    )
    ^
  File "/Users/admin/tears/code/.venv/lib/python3.13/site-packages/telegram/_bot.py", line 720, in _do_post
    result = await request.post(
             ^^^^^^^^^^^^^^^^^^^
    ...<6 lines>...
    )
    ^
  File "/Users/admin/tears/code/.venv/lib/python3.13/site-packages/telegram/request/_baserequest.py", line 202, in post
    result = await self._request_wrapper(
             ^^^^^^^^^^^^^^^^^^^^^^^^^^^^
    ...<7 lines>...
    )
    ^
  File "/Users/admin/tears/code/.venv/lib/python3.13/site-packages/telegram/request/_baserequest.py", line 385, in _request_wrapper
    raise Conflict(message)
telegram.error.Conflict: Conflict: terminated by other getUpdates request; make sure that only one bot instance is running
No error handlers are registered, logging exception.
Traceback (most recent call last):
  File "/Users/admin/tears/code/.venv/lib/python3.13/site-packages/telegram/ext/_utils/networkloop.py", line 115, in network_retry_loop
    if not await do_action():
           ^^^^^^^^^^^^^^^^^
  File "/Users/admin/tears/code/.venv/lib/python3.13/site-packages/telegram/ext/_utils/networkloop.py", line 108, in do_action
    return action_cb_task.result()
           ~~~~~~~~~~~~~~~~~~~~~^^
  File "/Users/admin/tears/code/.venv/lib/python3.13/site-packages/telegram/ext/_updater.py", line 376, in polling_action_cb
    updates = await self.bot.get_updates(
              ^^^^^^^^^^^^^^^^^^^^^^^^^^^
    ...<7 lines>...
    )
    ^
  File "/Users/admin/tears/code/.venv/lib/python3.13/site-packages/telegram/ext/_extbot.py", line 658, in get_updates
    updates = await super().get_updates(
              ^^^^^^^^^^^^^^^^^^^^^^^^^^
    ...<9 lines>...
    )
    ^
  File "/Users/admin/tears/code/.venv/lib/python3.13/site-packages/telegram/_bot.py", line 4605, in get_updates
    await self._post(
    ^^^^^^^^^^^^^^^^^
    ...<7 lines>...
    ),
    ^
  File "/Users/admin/tears/code/.venv/lib/python3.13/site-packages/telegram/_bot.py", line 691, in _post
    return await self._do_post(
           ^^^^^^^^^^^^^^^^^^^^
    ...<6 lines>...
    )
    ^
  File "/Users/admin/tears/code/.venv/lib/python3.13/site-packages/telegram/ext/_extbot.py", line 362, in _do_post
    return await super()._do_post(
           ^^^^^^^^^^^^^^^^^^^^^^^
    ...<6 lines>...
    )
    ^
  File "/Users/admin/tears/code/.venv/lib/python3.13/site-packages/telegram/_bot.py", line 720, in _do_post
    result = await request.post(
             ^^^^^^^^^^^^^^^^^^^
    ...<6 lines>...
    )
    ^
  File "/Users/admin/tears/code/.venv/lib/python3.13/site-packages/telegram/request/_baserequest.py", line 202, in post
    result = await self._request_wrapper(
             ^^^^^^^^^^^^^^^^^^^^^^^^^^^^
    ...<7 lines>...
    )
    ^
  File "/Users/admin/tears/code/.venv/lib/python3.13/site-packages/telegram/request/_baserequest.py", line 385, in _request_wrapper
    raise Conflict(message)
telegram.error.Conflict: Conflict: terminated by other getUpdates request; make sure that only one bot instance is running
No error handlers are registered, logging exception.
Traceback (most recent call last):
  File "/Users/admin/tears/code/.venv/lib/python3.13/site-packages/telegram/ext/_utils/networkloop.py", line 115, in network_retry_loop
    if not await do_action():
           ^^^^^^^^^^^^^^^^^
  File "/Users/admin/tears/code/.venv/lib/python3.13/site-packages/telegram/ext/_utils/networkloop.py", line 108, in do_action
    return action_cb_task.result()
           ~~~~~~~~~~~~~~~~~~~~~^^
  File "/Users/admin/tears/code/.venv/lib/python3.13/site-packages/telegram/ext/_updater.py", line 376, in polling_action_cb
    updates = await self.bot.get_updates(
              ^^^^^^^^^^^^^^^^^^^^^^^^^^^
    ...<7 lines>...
    )
    ^
  File "/Users/admin/tears/code/.venv/lib/python3.13/site-packages/telegram/ext/_extbot.py", line 658, in get_updates
    updates = await super().get_updates(
              ^^^^^^^^^^^^^^^^^^^^^^^^^^
    ...<9 lines>...
    )
    ^
  File "/Users/admin/tears/code/.venv/lib/python3.13/site-packages/telegram/_bot.py", line 4605, in get_updates
    await self._post(
    ^^^^^^^^^^^^^^^^^
    ...<7 lines>...
    ),
    ^
  File "/Users/admin/tears/code/.venv/lib/python3.13/site-packages/telegram/_bot.py", line 691, in _post
    return await self._do_post(
           ^^^^^^^^^^^^^^^^^^^^
    ...<6 lines>...
    )
    ^
  File "/Users/admin/tears/code/.venv/lib/python3.13/site-packages/telegram/ext/_extbot.py", line 362, in _do_post
    return await super()._do_post(
           ^^^^^^^^^^^^^^^^^^^^^^^
    ...<6 lines>...
    )
    ^
  File "/Users/admin/tears/code/.venv/lib/python3.13/site-packages/telegram/_bot.py", line 720, in _do_post
    result = await request.post(
             ^^^^^^^^^^^^^^^^^^^
    ...<6 lines>...
    )
    ^
  File "/Users/admin/tears/code/.venv/lib/python3.13/site-packages/telegram/request/_baserequest.py", line 202, in post
    result = await self._request_wrapper(
             ^^^^^^^^^^^^^^^^^^^^^^^^^^^^
    ...<7 lines>...
    )
    ^
  File "/Users/admin/tears/code/.venv/lib/python3.13/site-packages/telegram/request/_baserequest.py", line 385, in _request_wrapper
    raise Conflict(message)
telegram.error.Conflict: Conflict: terminated by other getUpdates request; make sure that only one bot instance is running
No error handlers are registered, logging exception.
Traceback (most recent call last):
  File "/Users/admin/tears/code/.venv/lib/python3.13/site-packages/telegram/ext/_utils/networkloop.py", line 115, in network_retry_loop
    if not await do_action():
           ^^^^^^^^^^^^^^^^^
  File "/Users/admin/tears/code/.venv/lib/python3.13/site-packages/telegram/ext/_utils/networkloop.py", line 108, in do_action
    return action_cb_task.result()
           ~~~~~~~~~~~~~~~~~~~~~^^
  File "/Users/admin/tears/code/.venv/lib/python3.13/site-packages/telegram/ext/_updater.py", line 376, in polling_action_cb
    updates = await self.bot.get_updates(
              ^^^^^^^^^^^^^^^^^^^^^^^^^^^
    ...<7 lines>...
    )
    ^
  File "/Users/admin/tears/code/.venv/lib/python3.13/site-packages/telegram/ext/_extbot.py", line 658, in get_updates
    updates = await super().get_updates(
              ^^^^^^^^^^^^^^^^^^^^^^^^^^
    ...<9 lines>...
    )
    ^
  File "/Users/admin/tears/code/.venv/lib/python3.13/site-packages/telegram/_bot.py", line 4605, in get_updates
    await self._post(
    ^^^^^^^^^^^^^^^^^
    ...<7 lines>...
    ),
    ^
  File "/Users/admin/tears/code/.venv/lib/python3.13/site-packages/telegram/_bot.py", line 691, in _post
    return await self._do_post(
           ^^^^^^^^^^^^^^^^^^^^
    ...<6 lines>...
    )
    ^
  File "/Users/admin/tears/code/.venv/lib/python3.13/site-packages/telegram/ext/_extbot.py", line 362, in _do_post
    return await super()._do_post(
           ^^^^^^^^^^^^^^^^^^^^^^^
    ...<6 lines>...
    )
    ^
  File "/Users/admin/tears/code/.venv/lib/python3.13/site-packages/telegram/_bot.py", line 720, in _do_post
    result = await request.post(
             ^^^^^^^^^^^^^^^^^^^
    ...<6 lines>...
    )
    ^
  File "/Users/admin/tears/code/.venv/lib/python3.13/site-packages/telegram/request/_baserequest.py", line 202, in post
    result = await self._request_wrapper(
             ^^^^^^^^^^^^^^^^^^^^^^^^^^^^
    ...<7 lines>...
    )
    ^
  File "/Users/admin/tears/code/.venv/lib/python3.13/site-packages/telegram/request/_baserequest.py", line 385, in _request_wrapper
    raise Conflict(message)
telegram.error.Conflict: Conflict: terminated by other getUpdates request; make sure that only one bot instance is running
No error handlers are registered, logging exception.
Traceback (most recent call last):
  File "/Users/admin/tears/code/.venv/lib/python3.13/site-packages/telegram/ext/_utils/networkloop.py", line 115, in network_retry_loop
    if not await do_action():
           ^^^^^^^^^^^^^^^^^
  File "/Users/admin/tears/code/.venv/lib/python3.13/site-packages/telegram/ext/_utils/networkloop.py", line 108, in do_action
    return action_cb_task.result()
           ~~~~~~~~~~~~~~~~~~~~~^^
  File "/Users/admin/tears/code/.venv/lib/python3.13/site-packages/telegram/ext/_updater.py", line 376, in polling_action_cb
    updates = await self.bot.get_updates(
              ^^^^^^^^^^^^^^^^^^^^^^^^^^^
    ...<7 lines>...
    )
    ^
  File "/Users/admin/tears/code/.venv/lib/python3.13/site-packages/telegram/ext/_extbot.py", line 658, in get_updates
    updates = await super().get_updates(
              ^^^^^^^^^^^^^^^^^^^^^^^^^^
    ...<9 lines>...
    )
    ^
  File "/Users/admin/tears/code/.venv/lib/python3.13/site-packages/telegram/_bot.py", line 4605, in get_updates
    await self._post(
    ^^^^^^^^^^^^^^^^^
    ...<7 lines>...
    ),
    ^
  File "/Users/admin/tears/code/.venv/lib/python3.13/site-packages/telegram/_bot.py", line 691, in _post
    return await self._do_post(
           ^^^^^^^^^^^^^^^^^^^^
    ...<6 lines>...
    )
    ^
  File "/Users/admin/tears/code/.venv/lib/python3.13/site-packages/telegram/ext/_extbot.py", line 362, in _do_post
    return await super()._do_post(
           ^^^^^^^^^^^^^^^^^^^^^^^
    ...<6 lines>...
    )
    ^
  File "/Users/admin/tears/code/.venv/lib/python3.13/site-packages/telegram/_bot.py", line 720, in _do_post
    result = await request.post(
             ^^^^^^^^^^^^^^^^^^^
    ...<6 lines>...
    )
    ^
  File "/Users/admin/tears/code/.venv/lib/python3.13/site-packages/telegram/request/_baserequest.py", line 202, in post
    result = await self._request_wrapper(
             ^^^^^^^^^^^^^^^^^^^^^^^^^^^^
    ...<7 lines>...
    )
    ^
  File "/Users/admin/tears/code/.venv/lib/python3.13/site-packages/telegram/request/_baserequest.py", line 385, in _request_wrapper
    raise Conflict(message)
telegram.error.Conflict: Conflict: terminated by other getUpdates request; make sure that only one bot instance is running
No error handlers are registered, logging exception.
Traceback (most recent call last):
  File "/Users/admin/tears/code/.venv/lib/python3.13/site-packages/telegram/ext/_utils/networkloop.py", line 115, in network_retry_loop
    if not await do_action():
           ^^^^^^^^^^^^^^^^^
  File "/Users/admin/tears/code/.venv/lib/python3.13/site-packages/telegram/ext/_utils/networkloop.py", line 108, in do_action
    return action_cb_task.result()
           ~~~~~~~~~~~~~~~~~~~~~^^
  File "/Users/admin/tears/code/.venv/lib/python3.13/site-packages/telegram/ext/_updater.py", line 376, in polling_action_cb
    updates = await self.bot.get_updates(
              ^^^^^^^^^^^^^^^^^^^^^^^^^^^
    ...<7 lines>...
    )
    ^
  File "/Users/admin/tears/code/.venv/lib/python3.13/site-packages/telegram/ext/_extbot.py", line 658, in get_updates
    updates = await super().get_updates(
              ^^^^^^^^^^^^^^^^^^^^^^^^^^
    ...<9 lines>...
    )
    ^
  File "/Users/admin/tears/code/.venv/lib/python3.13/site-packages/telegram/_bot.py", line 4605, in get_updates
    await self._post(
    ^^^^^^^^^^^^^^^^^
    ...<7 lines>...
    ),
    ^
  File "/Users/admin/tears/code/.venv/lib/python3.13/site-packages/telegram/_bot.py", line 691, in _post
    return await self._do_post(
           ^^^^^^^^^^^^^^^^^^^^
    ...<6 lines>...
    )
    ^
  File "/Users/admin/tears/code/.venv/lib/python3.13/site-packages/telegram/ext/_extbot.py", line 362, in _do_post
    return await super()._do_post(
           ^^^^^^^^^^^^^^^^^^^^^^^
    ...<6 lines>...
    )
    ^
  File "/Users/admin/tears/code/.venv/lib/python3.13/site-packages/telegram/_bot.py", line 720, in _do_post
    result = await request.post(
             ^^^^^^^^^^^^^^^^^^^
    ...<6 lines>...
    )
    ^
  File "/Users/admin/tears/code/.venv/lib/python3.13/site-packages/telegram/request/_baserequest.py", line 202, in post
    result = await self._request_wrapper(
             ^^^^^^^^^^^^^^^^^^^^^^^^^^^^
    ...<7 lines>...
    )
    ^
  File "/Users/admin/tears/code/.venv/lib/python3.13/site-packages/telegram/request/_baserequest.py", line 385, in _request_wrapper
    raise Conflict(message)
telegram.error.Conflict: Conflict: terminated by other getUpdates request; make sure that only one bot instance is running
No error handlers are registered, logging exception.
Traceback (most recent call last):
  File "/Users/admin/tears/code/.venv/lib/python3.13/site-packages/telegram/ext/_utils/networkloop.py", line 115, in network_retry_loop
    if not await do_action():
           ^^^^^^^^^^^^^^^^^
  File "/Users/admin/tears/code/.venv/lib/python3.13/site-packages/telegram/ext/_utils/networkloop.py", line 108, in do_action
    return action_cb_task.result()
           ~~~~~~~~~~~~~~~~~~~~~^^
  File "/Users/admin/tears/code/.venv/lib/python3.13/site-packages/telegram/ext/_updater.py", line 376, in polling_action_cb
    updates = await self.bot.get_updates(
              ^^^^^^^^^^^^^^^^^^^^^^^^^^^
    ...<7 lines>...
    )
    ^
  File "/Users/admin/tears/code/.venv/lib/python3.13/site-packages/telegram/ext/_extbot.py", line 658, in get_updates
    updates = await super().get_updates(
              ^^^^^^^^^^^^^^^^^^^^^^^^^^
    ...<9 lines>...
    )
    ^
  File "/Users/admin/tears/code/.venv/lib/python3.13/site-packages/telegram/_bot.py", line 4605, in get_updates
    await self._post(
    ^^^^^^^^^^^^^^^^^
    ...<7 lines>...
    ),
    ^
  File "/Users/admin/tears/code/.venv/lib/python3.13/site-packages/telegram/_bot.py", line 691, in _post
    return await self._do_post(
           ^^^^^^^^^^^^^^^^^^^^
    ...<6 lines>...
    )
    ^
  File "/Users/admin/tears/code/.venv/lib/python3.13/site-packages/telegram/ext/_extbot.py", line 362, in _do_post
    return await super()._do_post(
           ^^^^^^^^^^^^^^^^^^^^^^^
    ...<6 lines>...
    )
    ^
  File "/Users/admin/tears/code/.venv/lib/python3.13/site-packages/telegram/_bot.py", line 720, in _do_post
    result = await request.post(
             ^^^^^^^^^^^^^^^^^^^
    ...<6 lines>...
    )
    ^
  File "/Users/admin/tears/code/.venv/lib/python3.13/site-packages/telegram/request/_baserequest.py", line 202, in post
    result = await self._request_wrapper(
             ^^^^^^^^^^^^^^^^^^^^^^^^^^^^
    ...<7 lines>...
    )
    ^
  File "/Users/admin/tears/code/.venv/lib/python3.13/site-packages/telegram/request/_baserequest.py", line 385, in _request_wrapper
    raise Conflict(message)
telegram.error.Conflict: Conflict: terminated by other getUpdates request; make sure that only one bot instance is running
No error handlers are registered, logging exception.
Traceback (most recent call last):
  File "/Users/admin/tears/code/.venv/lib/python3.13/site-packages/telegram/ext/_utils/networkloop.py", line 115, in network_retry_loop
    if not await do_action():
           ^^^^^^^^^^^^^^^^^
  File "/Users/admin/tears/code/.venv/lib/python3.13/site-packages/telegram/ext/_utils/networkloop.py", line 108, in do_action
    return action_cb_task.result()
           ~~~~~~~~~~~~~~~~~~~~~^^
  File "/Users/admin/tears/code/.venv/lib/python3.13/site-packages/telegram/ext/_updater.py", line 376, in polling_action_cb
    updates = await self.bot.get_updates(
              ^^^^^^^^^^^^^^^^^^^^^^^^^^^
    ...<7 lines>...
    )
    ^
  File "/Users/admin/tears/code/.venv/lib/python3.13/site-packages/telegram/ext/_extbot.py", line 658, in get_updates
    updates = await super().get_updates(
              ^^^^^^^^^^^^^^^^^^^^^^^^^^
    ...<9 lines>...
    )
    ^
  File "/Users/admin/tears/code/.venv/lib/python3.13/site-packages/telegram/_bot.py", line 4605, in get_updates
    await self._post(
    ^^^^^^^^^^^^^^^^^
    ...<7 lines>...
    ),
    ^
  File "/Users/admin/tears/code/.venv/lib/python3.13/site-packages/telegram/_bot.py", line 691, in _post
    return await self._do_post(
           ^^^^^^^^^^^^^^^^^^^^
    ...<6 lines>...
    )
    ^
  File "/Users/admin/tears/code/.venv/lib/python3.13/site-packages/telegram/ext/_extbot.py", line 362, in _do_post
    return await super()._do_post(
           ^^^^^^^^^^^^^^^^^^^^^^^
    ...<6 lines>...
    )
    ^
  File "/Users/admin/tears/code/.venv/lib/python3.13/site-packages/telegram/_bot.py", line 720, in _do_post
    result = await request.post(
             ^^^^^^^^^^^^^^^^^^^
    ...<6 lines>...
    )
    ^
  File "/Users/admin/tears/code/.venv/lib/python3.13/site-packages/telegram/request/_baserequest.py", line 202, in post
    result = await self._request_wrapper(
             ^^^^^^^^^^^^^^^^^^^^^^^^^^^^
    ...<7 lines>...
    )
    ^
  File "/Users/admin/tears/code/.venv/lib/python3.13/site-packages/telegram/request/_baserequest.py", line 385, in _request_wrapper
    raise Conflict(message)
telegram.error.Conflict: Conflict: terminated by other getUpdates request; make sure that only one bot instance is running
No error handlers are registered, logging exception.
Traceback (most recent call last):
  File "/Users/admin/tears/code/.venv/lib/python3.13/site-packages/telegram/ext/_utils/networkloop.py", line 115, in network_retry_loop
    if not await do_action():
           ^^^^^^^^^^^^^^^^^
  File "/Users/admin/tears/code/.venv/lib/python3.13/site-packages/telegram/ext/_utils/networkloop.py", line 108, in do_action
    return action_cb_task.result()
           ~~~~~~~~~~~~~~~~~~~~~^^
  File "/Users/admin/tears/code/.venv/lib/python3.13/site-packages/telegram/ext/_updater.py", line 376, in polling_action_cb
    updates = await self.bot.get_updates(
              ^^^^^^^^^^^^^^^^^^^^^^^^^^^
    ...<7 lines>...
    )
    ^
  File "/Users/admin/tears/code/.venv/lib/python3.13/site-packages/telegram/ext/_extbot.py", line 658, in get_updates
    updates = await super().get_updates(
              ^^^^^^^^^^^^^^^^^^^^^^^^^^
    ...<9 lines>...
    )
    ^
  File "/Users/admin/tears/code/.venv/lib/python3.13/site-packages/telegram/_bot.py", line 4605, in get_updates
    await self._post(
    ^^^^^^^^^^^^^^^^^
    ...<7 lines>...
    ),
    ^
  File "/Users/admin/tears/code/.venv/lib/python3.13/site-packages/telegram/_bot.py", line 691, in _post
    return await self._do_post(
           ^^^^^^^^^^^^^^^^^^^^
    ...<6 lines>...
    )
    ^
  File "/Users/admin/tears/code/.venv/lib/python3.13/site-packages/telegram/ext/_extbot.py", line 362, in _do_post
    return await super()._do_post(
           ^^^^^^^^^^^^^^^^^^^^^^^
    ...<6 lines>...
    )
    ^
  File "/Users/admin/tears/code/.venv/lib/python3.13/site-packages/telegram/_bot.py", line 720, in _do_post
    result = await request.post(
             ^^^^^^^^^^^^^^^^^^^
    ...<6 lines>...
    )
    ^
  File "/Users/admin/tears/code/.venv/lib/python3.13/site-packages/telegram/request/_baserequest.py", line 202, in post
    result = await self._request_wrapper(
             ^^^^^^^^^^^^^^^^^^^^^^^^^^^^
    ...<7 lines>...
    )
    ^
  File "/Users/admin/tears/code/.venv/lib/python3.13/site-packages/telegram/request/_baserequest.py", line 385, in _request_wrapper
    raise Conflict(message)
telegram.error.Conflict: Conflict: terminated by other getUpdates request; make sure that only one bot instance is running
No error handlers are registered, logging exception.
Traceback (most recent call last):
  File "/Users/admin/tears/code/.venv/lib/python3.13/site-packages/telegram/ext/_utils/networkloop.py", line 115, in network_retry_loop
    if not await do_action():
           ^^^^^^^^^^^^^^^^^
  File "/Users/admin/tears/code/.venv/lib/python3.13/site-packages/telegram/ext/_utils/networkloop.py", line 108, in do_action
    return action_cb_task.result()
           ~~~~~~~~~~~~~~~~~~~~~^^
  File "/Users/admin/tears/code/.venv/lib/python3.13/site-packages/telegram/ext/_updater.py", line 376, in polling_action_cb
    updates = await self.bot.get_updates(
              ^^^^^^^^^^^^^^^^^^^^^^^^^^^
    ...<7 lines>...
    )
    ^
  File "/Users/admin/tears/code/.venv/lib/python3.13/site-packages/telegram/ext/_extbot.py", line 658, in get_updates
    updates = await super().get_updates(
              ^^^^^^^^^^^^^^^^^^^^^^^^^^
    ...<9 lines>...
    )
    ^
  File "/Users/admin/tears/code/.venv/lib/python3.13/site-packages/telegram/_bot.py", line 4605, in get_updates
    await self._post(
    ^^^^^^^^^^^^^^^^^
    ...<7 lines>...
    ),
    ^
  File "/Users/admin/tears/code/.venv/lib/python3.13/site-packages/telegram/_bot.py", line 691, in _post
    return await self._do_post(
           ^^^^^^^^^^^^^^^^^^^^
    ...<6 lines>...
    )
    ^
  File "/Users/admin/tears/code/.venv/lib/python3.13/site-packages/telegram/ext/_extbot.py", line 362, in _do_post
    return await super()._do_post(
           ^^^^^^^^^^^^^^^^^^^^^^^
    ...<6 lines>...
    )
    ^
  File "/Users/admin/tears/code/.venv/lib/python3.13/site-packages/telegram/_bot.py", line 720, in _do_post
    result = await request.post(
             ^^^^^^^^^^^^^^^^^^^
    ...<6 lines>...
    )
    ^
  File "/Users/admin/tears/code/.venv/lib/python3.13/site-packages/telegram/request/_baserequest.py", line 202, in post
    result = await self._request_wrapper(
             ^^^^^^^^^^^^^^^^^^^^^^^^^^^^
    ...<7 lines>...
    )
    ^
  File "/Users/admin/tears/code/.venv/lib/python3.13/site-packages/telegram/request/_baserequest.py", line 385, in _request_wrapper
    raise Conflict(message)
telegram.error.Conflict: Conflict: terminated by other getUpdates request; make sure that only one bot instance is running
No error handlers are registered, logging exception.
Traceback (most recent call last):
  File "/Users/admin/tears/code/.venv/lib/python3.13/site-packages/telegram/ext/_utils/networkloop.py", line 115, in network_retry_loop
    if not await do_action():
           ^^^^^^^^^^^^^^^^^
  File "/Users/admin/tears/code/.venv/lib/python3.13/site-packages/telegram/ext/_utils/networkloop.py", line 108, in do_action
    return action_cb_task.result()
           ~~~~~~~~~~~~~~~~~~~~~^^
  File "/Users/admin/tears/code/.venv/lib/python3.13/site-packages/telegram/ext/_updater.py", line 376, in polling_action_cb
    updates = await self.bot.get_updates(
              ^^^^^^^^^^^^^^^^^^^^^^^^^^^
    ...<7 lines>...
    )
    ^
  File "/Users/admin/tears/code/.venv/lib/python3.13/site-packages/telegram/ext/_extbot.py", line 658, in get_updates
    updates = await super().get_updates(
              ^^^^^^^^^^^^^^^^^^^^^^^^^^
    ...<9 lines>...
    )
    ^
  File "/Users/admin/tears/code/.venv/lib/python3.13/site-packages/telegram/_bot.py", line 4605, in get_updates
    await self._post(
    ^^^^^^^^^^^^^^^^^
    ...<7 lines>...
    ),
    ^
  File "/Users/admin/tears/code/.venv/lib/python3.13/site-packages/telegram/_bot.py", line 691, in _post
    return await self._do_post(
           ^^^^^^^^^^^^^^^^^^^^
    ...<6 lines>...
    )
    ^
  File "/Users/admin/tears/code/.venv/lib/python3.13/site-packages/telegram/ext/_extbot.py", line 362, in _do_post
    return await super()._do_post(
           ^^^^^^^^^^^^^^^^^^^^^^^
    ...<6 lines>...
    )
    ^
  File "/Users/admin/tears/code/.venv/lib/python3.13/site-packages/telegram/_bot.py", line 720, in _do_post
    result = await request.post(
             ^^^^^^^^^^^^^^^^^^^
    ...<6 lines>...
    )
    ^
  File "/Users/admin/tears/code/.venv/lib/python3.13/site-packages/telegram/request/_baserequest.py", line 202, in post
    result = await self._request_wrapper(
             ^^^^^^^^^^^^^^^^^^^^^^^^^^^^
    ...<7 lines>...
    )
    ^
  File "/Users/admin/tears/code/.venv/lib/python3.13/site-packages/telegram/request/_baserequest.py", line 385, in _request_wrapper
    raise Conflict(message)
telegram.error.Conflict: Conflict: terminated by other getUpdates request; make sure that only one bot instance is running
No error handlers are registered, logging exception.
Traceback (most recent call last):
  File "/Users/admin/tears/code/.venv/lib/python3.13/site-packages/telegram/ext/_utils/networkloop.py", line 115, in network_retry_loop
    if not await do_action():
           ^^^^^^^^^^^^^^^^^
  File "/Users/admin/tears/code/.venv/lib/python3.13/site-packages/telegram/ext/_utils/networkloop.py", line 108, in do_action
    return action_cb_task.result()
           ~~~~~~~~~~~~~~~~~~~~~^^
  File "/Users/admin/tears/code/.venv/lib/python3.13/site-packages/telegram/ext/_updater.py", line 376, in polling_action_cb
    updates = await self.bot.get_updates(
              ^^^^^^^^^^^^^^^^^^^^^^^^^^^
    ...<7 lines>...
    )
    ^
  File "/Users/admin/tears/code/.venv/lib/python3.13/site-packages/telegram/ext/_extbot.py", line 658, in get_updates
    updates = await super().get_updates(
              ^^^^^^^^^^^^^^^^^^^^^^^^^^
    ...<9 lines>...
    )
    ^
  File "/Users/admin/tears/code/.venv/lib/python3.13/site-packages/telegram/_bot.py", line 4605, in get_updates
    await self._post(
    ^^^^^^^^^^^^^^^^^
    ...<7 lines>...
    ),
    ^
  File "/Users/admin/tears/code/.venv/lib/python3.13/site-packages/telegram/_bot.py", line 691, in _post
    return await self._do_post(
           ^^^^^^^^^^^^^^^^^^^^
    ...<6 lines>...
    )
    ^
  File "/Users/admin/tears/code/.venv/lib/python3.13/site-packages/telegram/ext/_extbot.py", line 362, in _do_post
    return await super()._do_post(
           ^^^^^^^^^^^^^^^^^^^^^^^
    ...<6 lines>...
    )
    ^
  File "/Users/admin/tears/code/.venv/lib/python3.13/site-packages/telegram/_bot.py", line 720, in _do_post
    result = await request.post(
             ^^^^^^^^^^^^^^^^^^^
    ...<6 lines>...
    )
    ^
  File "/Users/admin/tears/code/.venv/lib/python3.13/site-packages/telegram/request/_baserequest.py", line 202, in post
    result = await self._request_wrapper(
             ^^^^^^^^^^^^^^^^^^^^^^^^^^^^
    ...<7 lines>...
    )
    ^
  File "/Users/admin/tears/code/.venv/lib/python3.13/site-packages/telegram/request/_baserequest.py", line 385, in _request_wrapper
    raise Conflict(message)
telegram.error.Conflict: Conflict: terminated by other getUpdates request; make sure that only one bot instance is running
No error handlers are registered, logging exception.
Traceback (most recent call last):
  File "/Users/admin/tears/code/.venv/lib/python3.13/site-packages/telegram/ext/_utils/networkloop.py", line 115, in network_retry_loop
    if not await do_action():
           ^^^^^^^^^^^^^^^^^
  File "/Users/admin/tears/code/.venv/lib/python3.13/site-packages/telegram/ext/_utils/networkloop.py", line 108, in do_action
    return action_cb_task.result()
           ~~~~~~~~~~~~~~~~~~~~~^^
  File "/Users/admin/tears/code/.venv/lib/python3.13/site-packages/telegram/ext/_updater.py", line 376, in polling_action_cb
    updates = await self.bot.get_updates(
              ^^^^^^^^^^^^^^^^^^^^^^^^^^^
    ...<7 lines>...
    )
    ^
  File "/Users/admin/tears/code/.venv/lib/python3.13/site-packages/telegram/ext/_extbot.py", line 658, in get_updates
    updates = await super().get_updates(
              ^^^^^^^^^^^^^^^^^^^^^^^^^^
    ...<9 lines>...
    )
    ^
  File "/Users/admin/tears/code/.venv/lib/python3.13/site-packages/telegram/_bot.py", line 4605, in get_updates
    await self._post(
    ^^^^^^^^^^^^^^^^^
    ...<7 lines>...
    ),
    ^
  File "/Users/admin/tears/code/.venv/lib/python3.13/site-packages/telegram/_bot.py", line 691, in _post
    return await self._do_post(
           ^^^^^^^^^^^^^^^^^^^^
    ...<6 lines>...
    )
    ^
  File "/Users/admin/tears/code/.venv/lib/python3.13/site-packages/telegram/ext/_extbot.py", line 362, in _do_post
    return await super()._do_post(
           ^^^^^^^^^^^^^^^^^^^^^^^
    ...<6 lines>...
    )
    ^
  File "/Users/admin/tears/code/.venv/lib/python3.13/site-packages/telegram/_bot.py", line 720, in _do_post
    result = await request.post(
             ^^^^^^^^^^^^^^^^^^^
    ...<6 lines>...
    )
    ^
  File "/Users/admin/tears/code/.venv/lib/python3.13/site-packages/telegram/request/_baserequest.py", line 202, in post
    result = await self._request_wrapper(
             ^^^^^^^^^^^^^^^^^^^^^^^^^^^^
    ...<7 lines>...
    )
    ^
  File "/Users/admin/tears/code/.venv/lib/python3.13/site-packages/telegram/request/_baserequest.py", line 385, in _request_wrapper
    raise Conflict(message)
telegram.error.Conflict: Conflict: terminated by other getUpdates request; make sure that only one bot instance is running
No error handlers are registered, logging exception.
Traceback (most recent call last):
  File "/Users/admin/tears/code/.venv/lib/python3.13/site-packages/telegram/ext/_utils/networkloop.py", line 115, in network_retry_loop
    if not await do_action():
           ^^^^^^^^^^^^^^^^^
  File "/Users/admin/tears/code/.venv/lib/python3.13/site-packages/telegram/ext/_utils/networkloop.py", line 108, in do_action
    return action_cb_task.result()
           ~~~~~~~~~~~~~~~~~~~~~^^
  File "/Users/admin/tears/code/.venv/lib/python3.13/site-packages/telegram/ext/_updater.py", line 376, in polling_action_cb
    updates = await self.bot.get_updates(
              ^^^^^^^^^^^^^^^^^^^^^^^^^^^
    ...<7 lines>...
    )
    ^
  File "/Users/admin/tears/code/.venv/lib/python3.13/site-packages/telegram/ext/_extbot.py", line 658, in get_updates
    updates = await super().get_updates(
              ^^^^^^^^^^^^^^^^^^^^^^^^^^
    ...<9 lines>...
    )
    ^
  File "/Users/admin/tears/code/.venv/lib/python3.13/site-packages/telegram/_bot.py", line 4605, in get_updates
    await self._post(
    ^^^^^^^^^^^^^^^^^
    ...<7 lines>...
    ),
    ^
  File "/Users/admin/tears/code/.venv/lib/python3.13/site-packages/telegram/_bot.py", line 691, in _post
    return await self._do_post(
           ^^^^^^^^^^^^^^^^^^^^
    ...<6 lines>...
    )
    ^
  File "/Users/admin/tears/code/.venv/lib/python3.13/site-packages/telegram/ext/_extbot.py", line 362, in _do_post
    return await super()._do_post(
           ^^^^^^^^^^^^^^^^^^^^^^^
    ...<6 lines>...
    )
    ^
  File "/Users/admin/tears/code/.venv/lib/python3.13/site-packages/telegram/_bot.py", line 720, in _do_post
    result = await request.post(
             ^^^^^^^^^^^^^^^^^^^
    ...<6 lines>...
    )
    ^
  File "/Users/admin/tears/code/.venv/lib/python3.13/site-packages/telegram/request/_baserequest.py", line 202, in post
    result = await self._request_wrapper(
             ^^^^^^^^^^^^^^^^^^^^^^^^^^^^
    ...<7 lines>...
    )
    ^
  File "/Users/admin/tears/code/.venv/lib/python3.13/site-packages/telegram/request/_baserequest.py", line 385, in _request_wrapper
    raise Conflict(message)
telegram.error.Conflict: Conflict: terminated by other getUpdates request; make sure that only one bot instance is running
No error handlers are registered, logging exception.
Traceback (most recent call last):
  File "/Users/admin/tears/code/.venv/lib/python3.13/site-packages/telegram/ext/_utils/networkloop.py", line 115, in network_retry_loop
    if not await do_action():
           ^^^^^^^^^^^^^^^^^
  File "/Users/admin/tears/code/.venv/lib/python3.13/site-packages/telegram/ext/_utils/networkloop.py", line 108, in do_action
    return action_cb_task.result()
           ~~~~~~~~~~~~~~~~~~~~~^^
  File "/Users/admin/tears/code/.venv/lib/python3.13/site-packages/telegram/ext/_updater.py", line 376, in polling_action_cb
    updates = await self.bot.get_updates(
              ^^^^^^^^^^^^^^^^^^^^^^^^^^^
    ...<7 lines>...
    )
    ^
  File "/Users/admin/tears/code/.venv/lib/python3.13/site-packages/telegram/ext/_extbot.py", line 658, in get_updates
    updates = await super().get_updates(
              ^^^^^^^^^^^^^^^^^^^^^^^^^^
    ...<9 lines>...
    )
    ^
  File "/Users/admin/tears/code/.venv/lib/python3.13/site-packages/telegram/_bot.py", line 4605, in get_updates
    await self._post(
    ^^^^^^^^^^^^^^^^^
    ...<7 lines>...
    ),
    ^
  File "/Users/admin/tears/code/.venv/lib/python3.13/site-packages/telegram/_bot.py", line 691, in _post
    return await self._do_post(
           ^^^^^^^^^^^^^^^^^^^^
    ...<6 lines>...
    )
    ^
  File "/Users/admin/tears/code/.venv/lib/python3.13/site-packages/telegram/ext/_extbot.py", line 362, in _do_post
    return await super()._do_post(
           ^^^^^^^^^^^^^^^^^^^^^^^
    ...<6 lines>...
    )
    ^
  File "/Users/admin/tears/code/.venv/lib/python3.13/site-packages/telegram/_bot.py", line 720, in _do_post
    result = await request.post(
             ^^^^^^^^^^^^^^^^^^^
    ...<6 lines>...
    )
    ^
  File "/Users/admin/tears/code/.venv/lib/python3.13/site-packages/telegram/request/_baserequest.py", line 202, in post
    result = await self._request_wrapper(
             ^^^^^^^^^^^^^^^^^^^^^^^^^^^^
    ...<7 lines>...
    )
    ^
  File "/Users/admin/tears/code/.venv/lib/python3.13/site-packages/telegram/request/_baserequest.py", line 385, in _request_wrapper
    raise Conflict(message)
telegram.error.Conflict: Conflict: terminated by other getUpdates request; make sure that only one bot instance is running
No error handlers are registered, logging exception.
Traceback (most recent call last):
  File "/Users/admin/tears/code/.venv/lib/python3.13/site-packages/telegram/ext/_utils/networkloop.py", line 115, in network_retry_loop
  File "/Users/admin/tears/code/.venv/lib/python3.13/site-packages/telegram/ext/_utils/networkloop.py", line 108, in do_action
  File "/Users/admin/tears/code/.venv/lib/python3.13/site-packages/telegram/ext/_updater.py", line 376, in polling_action_cb
  File "/Users/admin/tears/code/.venv/lib/python3.13/site-packages/telegram/ext/_extbot.py", line 658, in get_updates
  File "/Users/admin/tears/code/.venv/lib/python3.13/site-packages/telegram/_bot.py", line 4605, in get_updates
  File "/Users/admin/tears/code/.venv/lib/python3.13/site-packages/telegram/_bot.py", line 691, in _post
  File "/Users/admin/tears/code/.venv/lib/python3.13/site-packages/telegram/ext/_extbot.py", line 362, in _do_post
  File "/Users/admin/tears/code/.venv/lib/python3.13/site-packages/telegram/_bot.py", line 720, in _do_post
  File "/Users/admin/tears/code/.venv/lib/python3.13/site-packages/telegram/request/_baserequest.py", line 202, in post
  File "/Users/admin/tears/code/.venv/lib/python3.13/site-packages/telegram/request/_baserequest.py", line 385, in _request_wrapper
telegram.error.Conflict: Conflict: terminated by other getUpdates request; make sure that only one bot instance is running
No error handlers are registered, logging exception.
Traceback (most recent call last):
  File "/Users/admin/tears/code/.venv/lib/python3.13/site-packages/telegram/ext/_utils/networkloop.py", line 115, in network_retry_loop
  File "/Users/admin/tears/code/.venv/lib/python3.13/site-packages/telegram/ext/_utils/networkloop.py", line 108, in do_action
  File "/Users/admin/tears/code/.venv/lib/python3.13/site-packages/telegram/ext/_updater.py", line 376, in polling_action_cb
  File "/Users/admin/tears/code/.venv/lib/python3.13/site-packages/telegram/ext/_extbot.py", line 658, in get_updates
  File "/Users/admin/tears/code/.venv/lib/python3.13/site-packages/telegram/_bot.py", line 4605, in get_updates
  File "/Users/admin/tears/code/.venv/lib/python3.13/site-packages/telegram/_bot.py", line 691, in _post
  File "/Users/admin/tears/code/.venv/lib/python3.13/site-packages/telegram/ext/_extbot.py", line 362, in _do_post
  File "/Users/admin/tears/code/.venv/lib/python3.13/site-packages/telegram/_bot.py", line 720, in _do_post
  File "/Users/admin/tears/code/.venv/lib/python3.13/site-packages/telegram/request/_baserequest.py", line 202, in post
  File "/Users/admin/tears/code/.venv/lib/python3.13/site-packages/telegram/request/_baserequest.py", line 385, in _request_wrapper
telegram.error.Conflict: Conflict: terminated by other getUpdates request; make sure that only one bot instance is running
No error handlers are registered, logging exception.
Traceback (most recent call last):
  File "/Users/admin/tears/code/.venv/lib/python3.13/site-packages/telegram/ext/_utils/networkloop.py", line 115, in network_retry_loop
  File "/Users/admin/tears/code/.venv/lib/python3.13/site-packages/telegram/ext/_utils/networkloop.py", line 108, in do_action
  File "/Users/admin/tears/code/.venv/lib/python3.13/site-packages/telegram/ext/_updater.py", line 376, in polling_action_cb
  File "/Users/admin/tears/code/.venv/lib/python3.13/site-packages/telegram/ext/_extbot.py", line 658, in get_updates
  File "/Users/admin/tears/code/.venv/lib/python3.13/site-packages/telegram/_bot.py", line 4605, in get_updates
  File "/Users/admin/tears/code/.venv/lib/python3.13/site-packages/telegram/_bot.py", line 691, in _post
  File "/Users/admin/tears/code/.venv/lib/python3.13/site-packages/telegram/ext/_extbot.py", line 362, in _do_post
  File "/Users/admin/tears/code/.venv/lib/python3.13/site-packages/telegram/_bot.py", line 720, in _do_post
  File "/Users/admin/tears/code/.venv/lib/python3.13/site-packages/telegram/request/_baserequest.py", line 202, in post
  File "/Users/admin/tears/code/.venv/lib/python3.13/site-packages/telegram/request/_baserequest.py", line 385, in _request_wrapper
telegram.error.Conflict: Conflict: terminated by other getUpdates request; make sure that only one bot instance is running
No error handlers are registered, logging exception.
Traceback (most recent call last):
  File "/Users/admin/tears/code/.venv/lib/python3.13/site-packages/telegram/ext/_utils/networkloop.py", line 115, in network_retry_loop
  File "/Users/admin/tears/code/.venv/lib/python3.13/site-packages/telegram/ext/_utils/networkloop.py", line 108, in do_action
  File "/Users/admin/tears/code/.venv/lib/python3.13/site-packages/telegram/ext/_updater.py", line 376, in polling_action_cb
  File "/Users/admin/tears/code/.venv/lib/python3.13/site-packages/telegram/ext/_extbot.py", line 658, in get_updates
  File "/Users/admin/tears/code/.venv/lib/python3.13/site-packages/telegram/_bot.py", line 4605, in get_updates
  File "/Users/admin/tears/code/.venv/lib/python3.13/site-packages/telegram/_bot.py", line 691, in _post
  File "/Users/admin/tears/code/.venv/lib/python3.13/site-packages/telegram/ext/_extbot.py", line 362, in _do_post
  File "/Users/admin/tears/code/.venv/lib/python3.13/site-packages/telegram/_bot.py", line 720, in _do_post
  File "/Users/admin/tears/code/.venv/lib/python3.13/site-packages/telegram/request/_baserequest.py", line 202, in post
  File "/Users/admin/tears/code/.venv/lib/python3.13/site-packages/telegram/request/_baserequest.py", line 385, in _request_wrapper
telegram.error.Conflict: Conflict: terminated by other getUpdates request; make sure that only one bot instance is running
No error handlers are registered, logging exception.
Traceback (most recent call last):
  File "/Users/admin/tears/code/.venv/lib/python3.13/site-packages/telegram/ext/_utils/networkloop.py", line 115, in network_retry_loop
  File "/Users/admin/tears/code/.venv/lib/python3.13/site-packages/telegram/ext/_utils/networkloop.py", line 108, in do_action
  File "/Users/admin/tears/code/.venv/lib/python3.13/site-packages/telegram/ext/_updater.py", line 376, in polling_action_cb
  File "/Users/admin/tears/code/.venv/lib/python3.13/site-packages/telegram/ext/_extbot.py", line 658, in get_updates
  File "/Users/admin/tears/code/.venv/lib/python3.13/site-packages/telegram/_bot.py", line 4605, in get_updates
  File "/Users/admin/tears/code/.venv/lib/python3.13/site-packages/telegram/_bot.py", line 691, in _post
  File "/Users/admin/tears/code/.venv/lib/python3.13/site-packages/telegram/ext/_extbot.py", line 362, in _do_post
  File "/Users/admin/tears/code/.venv/lib/python3.13/site-packages/telegram/_bot.py", line 720, in _do_post
  File "/Users/admin/tears/code/.venv/lib/python3.13/site-packages/telegram/request/_baserequest.py", line 202, in post
  File "/Users/admin/tears/code/.venv/lib/python3.13/site-packages/telegram/request/_baserequest.py", line 385, in _request_wrapper
telegram.error.Conflict: Conflict: terminated by other getUpdates request; make sure that only one bot instance is running
No error handlers are registered, logging exception.
Traceback (most recent call last):
  File "/Users/admin/tears/code/.venv/lib/python3.13/site-packages/telegram/ext/_utils/networkloop.py", line 115, in network_retry_loop
  File "/Users/admin/tears/code/.venv/lib/python3.13/site-packages/telegram/ext/_utils/networkloop.py", line 108, in do_action
  File "/Users/admin/tears/code/.venv/lib/python3.13/site-packages/telegram/ext/_updater.py", line 376, in polling_action_cb
  File "/Users/admin/tears/code/.venv/lib/python3.13/site-packages/telegram/ext/_extbot.py", line 658, in get_updates
  File "/Users/admin/tears/code/.venv/lib/python3.13/site-packages/telegram/_bot.py", line 4605, in get_updates
  File "/Users/admin/tears/code/.venv/lib/python3.13/site-packages/telegram/_bot.py", line 691, in _post
  File "/Users/admin/tears/code/.venv/lib/python3.13/site-packages/telegram/ext/_extbot.py", line 362, in _do_post
  File "/Users/admin/tears/code/.venv/lib/python3.13/site-packages/telegram/_bot.py", line 720, in _do_post
  File "/Users/admin/tears/code/.venv/lib/python3.13/site-packages/telegram/request/_baserequest.py", line 202, in post
  File "/Users/admin/tears/code/.venv/lib/python3.13/site-packages/telegram/request/_baserequest.py", line 385, in _request_wrapper
telegram.error.Conflict: Conflict: terminated by other getUpdates request; make sure that only one bot instance is running
No error handlers are registered, logging exception.
Traceback (most recent call last):
  File "/Users/admin/tears/code/.venv/lib/python3.13/site-packages/telegram/ext/_utils/networkloop.py", line 115, in network_retry_loop
  File "/Users/admin/tears/code/.venv/lib/python3.13/site-packages/telegram/ext/_utils/networkloop.py", line 108, in do_action
  File "/Users/admin/tears/code/.venv/lib/python3.13/site-packages/telegram/ext/_updater.py", line 376, in polling_action_cb
  File "/Users/admin/tears/code/.venv/lib/python3.13/site-packages/telegram/ext/_extbot.py", line 658, in get_updates
  File "/Users/admin/tears/code/.venv/lib/python3.13/site-packages/telegram/_bot.py", line 4605, in get_updates
  File "/Users/admin/tears/code/.venv/lib/python3.13/site-packages/telegram/_bot.py", line 691, in _post
  File "/Users/admin/tears/code/.venv/lib/python3.13/site-packages/telegram/ext/_extbot.py", line 362, in _do_post
  File "/Users/admin/tears/code/.venv/lib/python3.13/site-packages/telegram/_bot.py", line 720, in _do_post
  File "/Users/admin/tears/code/.venv/lib/python3.13/site-packages/telegram/request/_baserequest.py", line 202, in post
  File "/Users/admin/tears/code/.venv/lib/python3.13/site-packages/telegram/request/_baserequest.py", line 385, in _request_wrapper
telegram.error.Conflict: Conflict: terminated by other getUpdates request; make sure that only one bot instance is running
No error handlers are registered, logging exception.
Traceback (most recent call last):
  File "/Users/admin/tears/code/.venv/lib/python3.13/site-packages/telegram/ext/_utils/networkloop.py", line 115, in network_retry_loop
  File "/Users/admin/tears/code/.venv/lib/python3.13/site-packages/telegram/ext/_utils/networkloop.py", line 108, in do_action
  File "/Users/admin/tears/code/.venv/lib/python3.13/site-packages/telegram/ext/_updater.py", line 376, in polling_action_cb
  File "/Users/admin/tears/code/.venv/lib/python3.13/site-packages/telegram/ext/_extbot.py", line 658, in get_updates
  File "/Users/admin/tears/code/.venv/lib/python3.13/site-packages/telegram/_bot.py", line 4605, in get_updates
  File "/Users/admin/tears/code/.venv/lib/python3.13/site-packages/telegram/_bot.py", line 691, in _post
  File "/Users/admin/tears/code/.venv/lib/python3.13/site-packages/telegram/ext/_extbot.py", line 362, in _do_post
  File "/Users/admin/tears/code/.venv/lib/python3.13/site-packages/telegram/_bot.py", line 720, in _do_post
  File "/Users/admin/tears/code/.venv/lib/python3.13/site-packages/telegram/request/_baserequest.py", line 202, in post
  File "/Users/admin/tears/code/.venv/lib/python3.13/site-packages/telegram/request/_baserequest.py", line 385, in _request_wrapper
telegram.error.Conflict: Conflict: terminated by other getUpdates request; make sure that only one bot instance is running
No error handlers are registered, logging exception.
Traceback (most recent call last):
  File "/Users/admin/tears/code/.venv/lib/python3.13/site-packages/telegram/ext/_utils/networkloop.py", line 115, in network_retry_loop
  File "/Users/admin/tears/code/.venv/lib/python3.13/site-packages/telegram/ext/_utils/networkloop.py", line 108, in do_action
  File "/Users/admin/tears/code/.venv/lib/python3.13/site-packages/telegram/ext/_updater.py", line 376, in polling_action_cb
  File "/Users/admin/tears/code/.venv/lib/python3.13/site-packages/telegram/ext/_extbot.py", line 658, in get_updates
  File "/Users/admin/tears/code/.venv/lib/python3.13/site-packages/telegram/_bot.py", line 4605, in get_updates
  File "/Users/admin/tears/code/.venv/lib/python3.13/site-packages/telegram/_bot.py", line 691, in _post
  File "/Users/admin/tears/code/.venv/lib/python3.13/site-packages/telegram/ext/_extbot.py", line 362, in _do_post
  File "/Users/admin/tears/code/.venv/lib/python3.13/site-packages/telegram/_bot.py", line 720, in _do_post
  File "/Users/admin/tears/code/.venv/lib/python3.13/site-packages/telegram/request/_baserequest.py", line 202, in post
  File "/Users/admin/tears/code/.venv/lib/python3.13/site-packages/telegram/request/_baserequest.py", line 385, in _request_wrapper
telegram.error.Conflict: Conflict: terminated by other getUpdates request; make sure that only one bot instance is running
No error handlers are registered, logging exception.
Traceback (most recent call last):
  File "/Users/admin/tears/code/.venv/lib/python3.13/site-packages/telegram/ext/_utils/networkloop.py", line 115, in network_retry_loop
  File "/Users/admin/tears/code/.venv/lib/python3.13/site-packages/telegram/ext/_utils/networkloop.py", line 108, in do_action
  File "/Users/admin/tears/code/.venv/lib/python3.13/site-packages/telegram/ext/_updater.py", line 376, in polling_action_cb
  File "/Users/admin/tears/code/.venv/lib/python3.13/site-packages/telegram/ext/_extbot.py", line 658, in get_updates
  File "/Users/admin/tears/code/.venv/lib/python3.13/site-packages/telegram/_bot.py", line 4605, in get_updates
  File "/Users/admin/tears/code/.venv/lib/python3.13/site-packages/telegram/_bot.py", line 691, in _post
  File "/Users/admin/tears/code/.venv/lib/python3.13/site-packages/telegram/ext/_extbot.py", line 362, in _do_post
  File "/Users/admin/tears/code/.venv/lib/python3.13/site-packages/telegram/_bot.py", line 720, in _do_post
  File "/Users/admin/tears/code/.venv/lib/python3.13/site-packages/telegram/request/_baserequest.py", line 202, in post
  File "/Users/admin/tears/code/.venv/lib/python3.13/site-packages/telegram/request/_baserequest.py", line 385, in _request_wrapper
telegram.error.Conflict: Conflict: terminated by other getUpdates request; make sure that only one bot instance is running
No error handlers are registered, logging exception.
Traceback (most recent call last):
  File "/Users/admin/tears/code/.venv/lib/python3.13/site-packages/telegram/ext/_utils/networkloop.py", line 115, in network_retry_loop
  File "/Users/admin/tears/code/.venv/lib/python3.13/site-packages/telegram/ext/_utils/networkloop.py", line 108, in do_action
  File "/Users/admin/tears/code/.venv/lib/python3.13/site-packages/telegram/ext/_updater.py", line 376, in polling_action_cb
  File "/Users/admin/tears/code/.venv/lib/python3.13/site-packages/telegram/ext/_extbot.py", line 658, in get_updates
  File "/Users/admin/tears/code/.venv/lib/python3.13/site-packages/telegram/_bot.py", line 4605, in get_updates
  File "/Users/admin/tears/code/.venv/lib/python3.13/site-packages/telegram/_bot.py", line 691, in _post
  File "/Users/admin/tears/code/.venv/lib/python3.13/site-packages/telegram/ext/_extbot.py", line 362, in _do_post
  File "/Users/admin/tears/code/.venv/lib/python3.13/site-packages/telegram/_bot.py", line 720, in _do_post
  File "/Users/admin/tears/code/.venv/lib/python3.13/site-packages/telegram/request/_baserequest.py", line 202, in post
  File "/Users/admin/tears/code/.venv/lib/python3.13/site-packages/telegram/request/_baserequest.py", line 385, in _request_wrapper
telegram.error.Conflict: Conflict: terminated by other getUpdates request; make sure that only one bot instance is running
No error handlers are registered, logging exception.
Traceback (most recent call last):
  File "/Users/admin/tears/code/.venv/lib/python3.13/site-packages/telegram/ext/_utils/networkloop.py", line 115, in network_retry_loop
  File "/Users/admin/tears/code/.venv/lib/python3.13/site-packages/telegram/ext/_utils/networkloop.py", line 108, in do_action
  File "/Users/admin/tears/code/.venv/lib/python3.13/site-packages/telegram/ext/_updater.py", line 376, in polling_action_cb
  File "/Users/admin/tears/code/.venv/lib/python3.13/site-packages/telegram/ext/_extbot.py", line 658, in get_updates
  File "/Users/admin/tears/code/.venv/lib/python3.13/site-packages/telegram/_bot.py", line 4605, in get_updates
  File "/Users/admin/tears/code/.venv/lib/python3.13/site-packages/telegram/_bot.py", line 691, in _post
  File "/Users/admin/tears/code/.venv/lib/python3.13/site-packages/telegram/ext/_extbot.py", line 362, in _do_post
  File "/Users/admin/tears/code/.venv/lib/python3.13/site-packages/telegram/_bot.py", line 720, in _do_post
  File "/Users/admin/tears/code/.venv/lib/python3.13/site-packages/telegram/request/_baserequest.py", line 202, in post
  File "/Users/admin/tears/code/.venv/lib/python3.13/site-packages/telegram/request/_baserequest.py", line 385, in _request_wrapper
telegram.error.Conflict: Conflict: terminated by other getUpdates request; make sure that only one bot instance is running
No error handlers are registered, logging exception.
Traceback (most recent call last):
  File "/Users/admin/tears/code/.venv/lib/python3.13/site-packages/telegram/ext/_utils/networkloop.py", line 115, in network_retry_loop
  File "/Users/admin/tears/code/.venv/lib/python3.13/site-packages/telegram/ext/_utils/networkloop.py", line 108, in do_action
  File "/Users/admin/tears/code/.venv/lib/python3.13/site-packages/telegram/ext/_updater.py", line 376, in polling_action_cb
  File "/Users/admin/tears/code/.venv/lib/python3.13/site-packages/telegram/ext/_extbot.py", line 658, in get_updates
  File "/Users/admin/tears/code/.venv/lib/python3.13/site-packages/telegram/_bot.py", line 4605, in get_updates
  File "/Users/admin/tears/code/.venv/lib/python3.13/site-packages/telegram/_bot.py", line 691, in _post
  File "/Users/admin/tears/code/.venv/lib/python3.13/site-packages/telegram/ext/_extbot.py", line 362, in _do_post
  File "/Users/admin/tears/code/.venv/lib/python3.13/site-packages/telegram/_bot.py", line 720, in _do_post
  File "/Users/admin/tears/code/.venv/lib/python3.13/site-packages/telegram/request/_baserequest.py", line 202, in post
  File "/Users/admin/tears/code/.venv/lib/python3.13/site-packages/telegram/request/_baserequest.py", line 385, in _request_wrapper
telegram.error.Conflict: Conflict: terminated by other getUpdates request; make sure that only one bot instance is running
No error handlers are registered, logging exception.
Traceback (most recent call last):
  File "/Users/admin/tears/code/.venv/lib/python3.13/site-packages/telegram/ext/_utils/networkloop.py", line 115, in network_retry_loop
  File "/Users/admin/tears/code/.venv/lib/python3.13/site-packages/telegram/ext/_utils/networkloop.py", line 108, in do_action
  File "/Users/admin/tears/code/.venv/lib/python3.13/site-packages/telegram/ext/_updater.py", line 376, in polling_action_cb
  File "/Users/admin/tears/code/.venv/lib/python3.13/site-packages/telegram/ext/_extbot.py", line 658, in get_updates
  File "/Users/admin/tears/code/.venv/lib/python3.13/site-packages/telegram/_bot.py", line 4605, in get_updates
  File "/Users/admin/tears/code/.venv/lib/python3.13/site-packages/telegram/_bot.py", line 691, in _post
  File "/Users/admin/tears/code/.venv/lib/python3.13/site-packages/telegram/ext/_extbot.py", line 362, in _do_post
  File "/Users/admin/tears/code/.venv/lib/python3.13/site-packages/telegram/_bot.py", line 720, in _do_post
  File "/Users/admin/tears/code/.venv/lib/python3.13/site-packages/telegram/request/_baserequest.py", line 202, in post
  File "/Users/admin/tears/code/.venv/lib/python3.13/site-packages/telegram/request/_baserequest.py", line 385, in _request_wrapper
telegram.error.Conflict: Conflict: terminated by other getUpdates request; make sure that only one bot instance is running
No error handlers are registered, logging exception.
Traceback (most recent call last):
  File "/Users/admin/tears/code/.venv/lib/python3.13/site-packages/telegram/ext/_utils/networkloop.py", line 115, in network_retry_loop
  File "/Users/admin/tears/code/.venv/lib/python3.13/site-packages/telegram/ext/_utils/networkloop.py", line 108, in do_action
  File "/Users/admin/tears/code/.venv/lib/python3.13/site-packages/telegram/ext/_updater.py", line 376, in polling_action_cb
  File "/Users/admin/tears/code/.venv/lib/python3.13/site-packages/telegram/ext/_extbot.py", line 658, in get_updates
  File "/Users/admin/tears/code/.venv/lib/python3.13/site-packages/telegram/_bot.py", line 4605, in get_updates
  File "/Users/admin/tears/code/.venv/lib/python3.13/site-packages/telegram/_bot.py", line 691, in _post
  File "/Users/admin/tears/code/.venv/lib/python3.13/site-packages/telegram/ext/_extbot.py", line 362, in _do_post
  File "/Users/admin/tears/code/.venv/lib/python3.13/site-packages/telegram/_bot.py", line 720, in _do_post
  File "/Users/admin/tears/code/.venv/lib/python3.13/site-packages/telegram/request/_baserequest.py", line 202, in post
  File "/Users/admin/tears/code/.venv/lib/python3.13/site-packages/telegram/request/_baserequest.py", line 385, in _request_wrapper
telegram.error.Conflict: Conflict: terminated by other getUpdates request; make sure that only one bot instance is running
No error handlers are registered, logging exception.
Traceback (most recent call last):
  File "/Users/admin/tears/code/.venv/lib/python3.13/site-packages/telegram/ext/_utils/networkloop.py", line 115, in network_retry_loop
  File "/Users/admin/tears/code/.venv/lib/python3.13/site-packages/telegram/ext/_utils/networkloop.py", line 108, in do_action
  File "/Users/admin/tears/code/.venv/lib/python3.13/site-packages/telegram/ext/_updater.py", line 376, in polling_action_cb
  File "/Users/admin/tears/code/.venv/lib/python3.13/site-packages/telegram/ext/_extbot.py", line 658, in get_updates
  File "/Users/admin/tears/code/.venv/lib/python3.13/site-packages/telegram/_bot.py", line 4605, in get_updates
  File "/Users/admin/tears/code/.venv/lib/python3.13/site-packages/telegram/_bot.py", line 691, in _post
  File "/Users/admin/tears/code/.venv/lib/python3.13/site-packages/telegram/ext/_extbot.py", line 362, in _do_post
  File "/Users/admin/tears/code/.venv/lib/python3.13/site-packages/telegram/_bot.py", line 720, in _do_post
  File "/Users/admin/tears/code/.venv/lib/python3.13/site-packages/telegram/request/_baserequest.py", line 202, in post
  File "/Users/admin/tears/code/.venv/lib/python3.13/site-packages/telegram/request/_baserequest.py", line 385, in _request_wrapper
telegram.error.Conflict: Conflict: terminated by other getUpdates request; make sure that only one bot instance is running
No error handlers are registered, logging exception.
Traceback (most recent call last):
  File "/Users/admin/tears/code/.venv/lib/python3.13/site-packages/telegram/ext/_utils/networkloop.py", line 115, in network_retry_loop
  File "/Users/admin/tears/code/.venv/lib/python3.13/site-packages/telegram/ext/_utils/networkloop.py", line 108, in do_action
  File "/Users/admin/tears/code/.venv/lib/python3.13/site-packages/telegram/ext/_updater.py", line 376, in polling_action_cb
  File "/Users/admin/tears/code/.venv/lib/python3.13/site-packages/telegram/ext/_extbot.py", line 658, in get_updates
  File "/Users/admin/tears/code/.venv/lib/python3.13/site-packages/telegram/_bot.py", line 4605, in get_updates
  File "/Users/admin/tears/code/.venv/lib/python3.13/site-packages/telegram/_bot.py", line 691, in _post
  File "/Users/admin/tears/code/.venv/lib/python3.13/site-packages/telegram/ext/_extbot.py", line 362, in _do_post
  File "/Users/admin/tears/code/.venv/lib/python3.13/site-packages/telegram/_bot.py", line 720, in _do_post
  File "/Users/admin/tears/code/.venv/lib/python3.13/site-packages/telegram/request/_baserequest.py", line 202, in post
  File "/Users/admin/tears/code/.venv/lib/python3.13/site-packages/telegram/request/_baserequest.py", line 385, in _request_wrapper
telegram.error.Conflict: Conflict: terminated by other getUpdates request; make sure that only one bot instance is running
No error handlers are registered, logging exception.
Traceback (most recent call last):
  File "/Users/admin/tears/code/.venv/lib/python3.13/site-packages/telegram/ext/_utils/networkloop.py", line 115, in network_retry_loop
  File "/Users/admin/tears/code/.venv/lib/python3.13/site-packages/telegram/ext/_utils/networkloop.py", line 108, in do_action
  File "/Users/admin/tears/code/.venv/lib/python3.13/site-packages/telegram/ext/_updater.py", line 376, in polling_action_cb
  File "/Users/admin/tears/code/.venv/lib/python3.13/site-packages/telegram/ext/_extbot.py", line 658, in get_updates
  File "/Users/admin/tears/code/.venv/lib/python3.13/site-packages/telegram/_bot.py", line 4605, in get_updates
  File "/Users/admin/tears/code/.venv/lib/python3.13/site-packages/telegram/_bot.py", line 691, in _post
  File "/Users/admin/tears/code/.venv/lib/python3.13/site-packages/telegram/ext/_extbot.py", line 362, in _do_post
  File "/Users/admin/tears/code/.venv/lib/python3.13/site-packages/telegram/_bot.py", line 720, in _do_post
  File "/Users/admin/tears/code/.venv/lib/python3.13/site-packages/telegram/request/_baserequest.py", line 202, in post
  File "/Users/admin/tears/code/.venv/lib/python3.13/site-packages/telegram/request/_baserequest.py", line 385, in _request_wrapper
telegram.error.Conflict: Conflict: terminated by other getUpdates request; make sure that only one bot instance is running
No error handlers are registered, logging exception.
Traceback (most recent call last):
  File "/Users/admin/tears/code/.venv/lib/python3.13/site-packages/telegram/ext/_utils/networkloop.py", line 115, in network_retry_loop
  File "/Users/admin/tears/code/.venv/lib/python3.13/site-packages/telegram/ext/_utils/networkloop.py", line 108, in do_action
  File "/Users/admin/tears/code/.venv/lib/python3.13/site-packages/telegram/ext/_updater.py", line 376, in polling_action_cb
  File "/Users/admin/tears/code/.venv/lib/python3.13/site-packages/telegram/ext/_extbot.py", line 658, in get_updates
  File "/Users/admin/tears/code/.venv/lib/python3.13/site-packages/telegram/_bot.py", line 4605, in get_updates
  File "/Users/admin/tears/code/.venv/lib/python3.13/site-packages/telegram/_bot.py", line 691, in _post
  File "/Users/admin/tears/code/.venv/lib/python3.13/site-packages/telegram/ext/_extbot.py", line 362, in _do_post
  File "/Users/admin/tears/code/.venv/lib/python3.13/site-packages/telegram/_bot.py", line 720, in _do_post
  File "/Users/admin/tears/code/.venv/lib/python3.13/site-packages/telegram/request/_baserequest.py", line 202, in post
  File "/Users/admin/tears/code/.venv/lib/python3.13/site-packages/telegram/request/_baserequest.py", line 385, in _request_wrapper
telegram.error.Conflict: Conflict: terminated by other getUpdates request; make sure that only one bot instance is running
No error handlers are registered, logging exception.
Traceback (most recent call last):
  File "/Users/admin/tears/code/.venv/lib/python3.13/site-packages/telegram/ext/_utils/networkloop.py", line 115, in network_retry_loop
  File "/Users/admin/tears/code/.venv/lib/python3.13/site-packages/telegram/ext/_utils/networkloop.py", line 108, in do_action
  File "/Users/admin/tears/code/.venv/lib/python3.13/site-packages/telegram/ext/_updater.py", line 376, in polling_action_cb
  File "/Users/admin/tears/code/.venv/lib/python3.13/site-packages/telegram/ext/_extbot.py", line 658, in get_updates
  File "/Users/admin/tears/code/.venv/lib/python3.13/site-packages/telegram/_bot.py", line 4605, in get_updates
  File "/Users/admin/tears/code/.venv/lib/python3.13/site-packages/telegram/_bot.py", line 691, in _post
  File "/Users/admin/tears/code/.venv/lib/python3.13/site-packages/telegram/ext/_extbot.py", line 362, in _do_post
  File "/Users/admin/tears/code/.venv/lib/python3.13/site-packages/telegram/_bot.py", line 720, in _do_post
  File "/Users/admin/tears/code/.venv/lib/python3.13/site-packages/telegram/request/_baserequest.py", line 202, in post
  File "/Users/admin/tears/code/.venv/lib/python3.13/site-packages/telegram/request/_baserequest.py", line 385, in _request_wrapper
telegram.error.Conflict: Conflict: terminated by other getUpdates request; make sure that only one bot instance is running
No error handlers are registered, logging exception.
Traceback (most recent call last):
  File "/Users/admin/tears/code/.venv/lib/python3.13/site-packages/telegram/ext/_utils/networkloop.py", line 115, in network_retry_loop
  File "/Users/admin/tears/code/.venv/lib/python3.13/site-packages/telegram/ext/_utils/networkloop.py", line 108, in do_action
  File "/Users/admin/tears/code/.venv/lib/python3.13/site-packages/telegram/ext/_updater.py", line 376, in polling_action_cb
  File "/Users/admin/tears/code/.venv/lib/python3.13/site-packages/telegram/ext/_extbot.py", line 658, in get_updates
  File "/Users/admin/tears/code/.venv/lib/python3.13/site-packages/telegram/_bot.py", line 4605, in get_updates
  File "/Users/admin/tears/code/.venv/lib/python3.13/site-packages/telegram/_bot.py", line 691, in _post
  File "/Users/admin/tears/code/.venv/lib/python3.13/site-packages/telegram/ext/_extbot.py", line 362, in _do_post
  File "/Users/admin/tears/code/.venv/lib/python3.13/site-packages/telegram/_bot.py", line 720, in _do_post
  File "/Users/admin/tears/code/.venv/lib/python3.13/site-packages/telegram/request/_baserequest.py", line 202, in post
  File "/Users/admin/tears/code/.venv/lib/python3.13/site-packages/telegram/request/_baserequest.py", line 385, in _request_wrapper
telegram.error.Conflict: Conflict: terminated by other getUpdates request; make sure that only one bot instance is running
No error handlers are registered, logging exception.
Traceback (most recent call last):
  File "/Users/admin/tears/code/.venv/lib/python3.13/site-packages/telegram/ext/_utils/networkloop.py", line 115, in network_retry_loop
  File "/Users/admin/tears/code/.venv/lib/python3.13/site-packages/telegram/ext/_utils/networkloop.py", line 108, in do_action
  File "/Users/admin/tears/code/.venv/lib/python3.13/site-packages/telegram/ext/_updater.py", line 376, in polling_action_cb
  File "/Users/admin/tears/code/.venv/lib/python3.13/site-packages/telegram/ext/_extbot.py", line 658, in get_updates
  File "/Users/admin/tears/code/.venv/lib/python3.13/site-packages/telegram/_bot.py", line 4605, in get_updates
  File "/Users/admin/tears/code/.venv/lib/python3.13/site-packages/telegram/_bot.py", line 691, in _post
  File "/Users/admin/tears/code/.venv/lib/python3.13/site-packages/telegram/ext/_extbot.py", line 362, in _do_post
  File "/Users/admin/tears/code/.venv/lib/python3.13/site-packages/telegram/_bot.py", line 720, in _do_post
  File "/Users/admin/tears/code/.venv/lib/python3.13/site-packages/telegram/request/_baserequest.py", line 202, in post
  File "/Users/admin/tears/code/.venv/lib/python3.13/site-packages/telegram/request/_baserequest.py", line 385, in _request_wrapper
telegram.error.Conflict: Conflict: terminated by other getUpdates request; make sure that only one bot instance is running
No error handlers are registered, logging exception.
Traceback (most recent call last):
  File "/Users/admin/tears/code/.venv/lib/python3.13/site-packages/telegram/ext/_utils/networkloop.py", line 115, in network_retry_loop
  File "/Users/admin/tears/code/.venv/lib/python3.13/site-packages/telegram/ext/_utils/networkloop.py", line 108, in do_action
  File "/Users/admin/tears/code/.venv/lib/python3.13/site-packages/telegram/ext/_updater.py", line 376, in polling_action_cb
  File "/Users/admin/tears/code/.venv/lib/python3.13/site-packages/telegram/ext/_extbot.py", line 658, in get_updates
  File "/Users/admin/tears/code/.venv/lib/python3.13/site-packages/telegram/_bot.py", line 4605, in get_updates
  File "/Users/admin/tears/code/.venv/lib/python3.13/site-packages/telegram/_bot.py", line 691, in _post
  File "/Users/admin/tears/code/.venv/lib/python3.13/site-packages/telegram/ext/_extbot.py", line 362, in _do_post
  File "/Users/admin/tears/code/.venv/lib/python3.13/site-packages/telegram/_bot.py", line 720, in _do_post
  File "/Users/admin/tears/code/.venv/lib/python3.13/site-packages/telegram/request/_baserequest.py", line 202, in post
  File "/Users/admin/tears/code/.venv/lib/python3.13/site-packages/telegram/request/_baserequest.py", line 385, in _request_wrapper
telegram.error.Conflict: Conflict: terminated by other getUpdates request; make sure that only one bot instance is running
No error handlers are registered, logging exception.
Traceback (most recent call last):
  File "/Users/admin/tears/code/.venv/lib/python3.13/site-packages/telegram/ext/_utils/networkloop.py", line 115, in network_retry_loop
  File "/Users/admin/tears/code/.venv/lib/python3.13/site-packages/telegram/ext/_utils/networkloop.py", line 108, in do_action
  File "/Users/admin/tears/code/.venv/lib/python3.13/site-packages/telegram/ext/_updater.py", line 376, in polling_action_cb
  File "/Users/admin/tears/code/.venv/lib/python3.13/site-packages/telegram/ext/_extbot.py", line 658, in get_updates
  File "/Users/admin/tears/code/.venv/lib/python3.13/site-packages/telegram/_bot.py", line 4605, in get_updates
  File "/Users/admin/tears/code/.venv/lib/python3.13/site-packages/telegram/_bot.py", line 691, in _post
  File "/Users/admin/tears/code/.venv/lib/python3.13/site-packages/telegram/ext/_extbot.py", line 362, in _do_post
  File "/Users/admin/tears/code/.venv/lib/python3.13/site-packages/telegram/_bot.py", line 720, in _do_post
  File "/Users/admin/tears/code/.venv/lib/python3.13/site-packages/telegram/request/_baserequest.py", line 202, in post
  File "/Users/admin/tears/code/.venv/lib/python3.13/site-packages/telegram/request/_baserequest.py", line 385, in _request_wrapper
telegram.error.Conflict: Conflict: terminated by other getUpdates request; make sure that only one bot instance is running
No error handlers are registered, logging exception.
Traceback (most recent call last):
  File "/Users/admin/tears/code/.venv/lib/python3.13/site-packages/telegram/ext/_utils/networkloop.py", line 115, in network_retry_loop
  File "/Users/admin/tears/code/.venv/lib/python3.13/site-packages/telegram/ext/_utils/networkloop.py", line 108, in do_action
  File "/Users/admin/tears/code/.venv/lib/python3.13/site-packages/telegram/ext/_updater.py", line 376, in polling_action_cb
  File "/Users/admin/tears/code/.venv/lib/python3.13/site-packages/telegram/ext/_extbot.py", line 658, in get_updates
  File "/Users/admin/tears/code/.venv/lib/python3.13/site-packages/telegram/_bot.py", line 4605, in get_updates
  File "/Users/admin/tears/code/.venv/lib/python3.13/site-packages/telegram/_bot.py", line 691, in _post
  File "/Users/admin/tears/code/.venv/lib/python3.13/site-packages/telegram/ext/_extbot.py", line 362, in _do_post
  File "/Users/admin/tears/code/.venv/lib/python3.13/site-packages/telegram/_bot.py", line 720, in _do_post
  File "/Users/admin/tears/code/.venv/lib/python3.13/site-packages/telegram/request/_baserequest.py", line 202, in post
  File "/Users/admin/tears/code/.venv/lib/python3.13/site-packages/telegram/request/_baserequest.py", line 385, in _request_wrapper
telegram.error.Conflict: Conflict: terminated by other getUpdates request; make sure that only one bot instance is running
No error handlers are registered, logging exception.
Traceback (most recent call last):
  File "/Users/admin/tears/code/.venv/lib/python3.13/site-packages/telegram/ext/_utils/networkloop.py", line 115, in network_retry_loop
  File "/Users/admin/tears/code/.venv/lib/python3.13/site-packages/telegram/ext/_utils/networkloop.py", line 108, in do_action
  File "/Users/admin/tears/code/.venv/lib/python3.13/site-packages/telegram/ext/_updater.py", line 376, in polling_action_cb
  File "/Users/admin/tears/code/.venv/lib/python3.13/site-packages/telegram/ext/_extbot.py", line 658, in get_updates
  File "/Users/admin/tears/code/.venv/lib/python3.13/site-packages/telegram/_bot.py", line 4605, in get_updates
  File "/Users/admin/tears/code/.venv/lib/python3.13/site-packages/telegram/_bot.py", line 691, in _post
  File "/Users/admin/tears/code/.venv/lib/python3.13/site-packages/telegram/ext/_extbot.py", line 362, in _do_post
  File "/Users/admin/tears/code/.venv/lib/python3.13/site-packages/telegram/_bot.py", line 720, in _do_post
  File "/Users/admin/tears/code/.venv/lib/python3.13/site-packages/telegram/request/_baserequest.py", line 202, in post
  File "/Users/admin/tears/code/.venv/lib/python3.13/site-packages/telegram/request/_baserequest.py", line 385, in _request_wrapper
telegram.error.Conflict: Conflict: terminated by other getUpdates request; make sure that only one bot instance is running
No error handlers are registered, logging exception.
Traceback (most recent call last):
  File "/Users/admin/tears/code/.venv/lib/python3.13/site-packages/telegram/ext/_utils/networkloop.py", line 115, in network_retry_loop
  File "/Users/admin/tears/code/.venv/lib/python3.13/site-packages/telegram/ext/_utils/networkloop.py", line 108, in do_action
  File "/Users/admin/tears/code/.venv/lib/python3.13/site-packages/telegram/ext/_updater.py", line 376, in polling_action_cb
  File "/Users/admin/tears/code/.venv/lib/python3.13/site-packages/telegram/ext/_extbot.py", line 658, in get_updates
  File "/Users/admin/tears/code/.venv/lib/python3.13/site-packages/telegram/_bot.py", line 4605, in get_updates
  File "/Users/admin/tears/code/.venv/lib/python3.13/site-packages/telegram/_bot.py", line 691, in _post
  File "/Users/admin/tears/code/.venv/lib/python3.13/site-packages/telegram/ext/_extbot.py", line 362, in _do_post
  File "/Users/admin/tears/code/.venv/lib/python3.13/site-packages/telegram/_bot.py", line 720, in _do_post
  File "/Users/admin/tears/code/.venv/lib/python3.13/site-packages/telegram/request/_baserequest.py", line 202, in post
  File "/Users/admin/tears/code/.venv/lib/python3.13/site-packages/telegram/request/_baserequest.py", line 385, in _request_wrapper
telegram.error.Conflict: Conflict: terminated by other getUpdates request; make sure that only one bot instance is running
No error handlers are registered, logging exception.
Traceback (most recent call last):
  File "/Users/admin/tears/code/.venv/lib/python3.13/site-packages/telegram/ext/_utils/networkloop.py", line 115, in network_retry_loop
  File "/Users/admin/tears/code/.venv/lib/python3.13/site-packages/telegram/ext/_utils/networkloop.py", line 108, in do_action
  File "/Users/admin/tears/code/.venv/lib/python3.13/site-packages/telegram/ext/_updater.py", line 376, in polling_action_cb
  File "/Users/admin/tears/code/.venv/lib/python3.13/site-packages/telegram/ext/_extbot.py", line 658, in get_updates
  File "/Users/admin/tears/code/.venv/lib/python3.13/site-packages/telegram/_bot.py", line 4605, in get_updates
  File "/Users/admin/tears/code/.venv/lib/python3.13/site-packages/telegram/_bot.py", line 691, in _post
  File "/Users/admin/tears/code/.venv/lib/python3.13/site-packages/telegram/ext/_extbot.py", line 362, in _do_post
  File "/Users/admin/tears/code/.venv/lib/python3.13/site-packages/telegram/_bot.py", line 720, in _do_post
  File "/Users/admin/tears/code/.venv/lib/python3.13/site-packages/telegram/request/_baserequest.py", line 202, in post
  File "/Users/admin/tears/code/.venv/lib/python3.13/site-packages/telegram/request/_baserequest.py", line 385, in _request_wrapper
telegram.error.Conflict: Conflict: terminated by other getUpdates request; make sure that only one bot instance is running
No error handlers are registered, logging exception.
Traceback (most recent call last):
  File "/Users/admin/tears/code/.venv/lib/python3.13/site-packages/telegram/ext/_utils/networkloop.py", line 115, in network_retry_loop
  File "/Users/admin/tears/code/.venv/lib/python3.13/site-packages/telegram/ext/_utils/networkloop.py", line 108, in do_action
  File "/Users/admin/tears/code/.venv/lib/python3.13/site-packages/telegram/ext/_updater.py", line 376, in polling_action_cb
  File "/Users/admin/tears/code/.venv/lib/python3.13/site-packages/telegram/ext/_extbot.py", line 658, in get_updates
  File "/Users/admin/tears/code/.venv/lib/python3.13/site-packages/telegram/_bot.py", line 4605, in get_updates
  File "/Users/admin/tears/code/.venv/lib/python3.13/site-packages/telegram/_bot.py", line 691, in _post
  File "/Users/admin/tears/code/.venv/lib/python3.13/site-packages/telegram/ext/_extbot.py", line 362, in _do_post
  File "/Users/admin/tears/code/.venv/lib/python3.13/site-packages/telegram/_bot.py", line 720, in _do_post
  File "/Users/admin/tears/code/.venv/lib/python3.13/site-packages/telegram/request/_baserequest.py", line 202, in post
  File "/Users/admin/tears/code/.venv/lib/python3.13/site-packages/telegram/request/_baserequest.py", line 385, in _request_wrapper
telegram.error.Conflict: Conflict: terminated by other getUpdates request; make sure that only one bot instance is running
No error handlers are registered, logging exception.
Traceback (most recent call last):
  File "/Users/admin/tears/code/.venv/lib/python3.13/site-packages/telegram/ext/_utils/networkloop.py", line 115, in network_retry_loop
  File "/Users/admin/tears/code/.venv/lib/python3.13/site-packages/telegram/ext/_utils/networkloop.py", line 108, in do_action
  File "/Users/admin/tears/code/.venv/lib/python3.13/site-packages/telegram/ext/_updater.py", line 376, in polling_action_cb
  File "/Users/admin/tears/code/.venv/lib/python3.13/site-packages/telegram/ext/_extbot.py", line 658, in get_updates
  File "/Users/admin/tears/code/.venv/lib/python3.13/site-packages/telegram/_bot.py", line 4605, in get_updates
  File "/Users/admin/tears/code/.venv/lib/python3.13/site-packages/telegram/_bot.py", line 691, in _post
  File "/Users/admin/tears/code/.venv/lib/python3.13/site-packages/telegram/ext/_extbot.py", line 362, in _do_post
  File "/Users/admin/tears/code/.venv/lib/python3.13/site-packages/telegram/_bot.py", line 720, in _do_post
  File "/Users/admin/tears/code/.venv/lib/python3.13/site-packages/telegram/request/_baserequest.py", line 202, in post
  File "/Users/admin/tears/code/.venv/lib/python3.13/site-packages/telegram/request/_baserequest.py", line 385, in _request_wrapper
telegram.error.Conflict: Conflict: terminated by other getUpdates request; make sure that only one bot instance is running
No error handlers are registered, logging exception.
Traceback (most recent call last):
  File "/Users/admin/tears/code/.venv/lib/python3.13/site-packages/telegram/ext/_utils/networkloop.py", line 115, in network_retry_loop
  File "/Users/admin/tears/code/.venv/lib/python3.13/site-packages/telegram/ext/_utils/networkloop.py", line 108, in do_action
  File "/Users/admin/tears/code/.venv/lib/python3.13/site-packages/telegram/ext/_updater.py", line 376, in polling_action_cb
  File "/Users/admin/tears/code/.venv/lib/python3.13/site-packages/telegram/ext/_extbot.py", line 658, in get_updates
  File "/Users/admin/tears/code/.venv/lib/python3.13/site-packages/telegram/_bot.py", line 4605, in get_updates
  File "/Users/admin/tears/code/.venv/lib/python3.13/site-packages/telegram/_bot.py", line 691, in _post
  File "/Users/admin/tears/code/.venv/lib/python3.13/site-packages/telegram/ext/_extbot.py", line 362, in _do_post
  File "/Users/admin/tears/code/.venv/lib/python3.13/site-packages/telegram/_bot.py", line 720, in _do_post
  File "/Users/admin/tears/code/.venv/lib/python3.13/site-packages/telegram/request/_baserequest.py", line 202, in post
  File "/Users/admin/tears/code/.venv/lib/python3.13/site-packages/telegram/request/_baserequest.py", line 385, in _request_wrapper
telegram.error.Conflict: Conflict: terminated by other getUpdates request; make sure that only one bot instance is running
No error handlers are registered, logging exception.
Traceback (most recent call last):
  File "/Users/admin/tears/code/.venv/lib/python3.13/site-packages/telegram/ext/_utils/networkloop.py", line 115, in network_retry_loop
  File "/Users/admin/tears/code/.venv/lib/python3.13/site-packages/telegram/ext/_utils/networkloop.py", line 108, in do_action
  File "/Users/admin/tears/code/.venv/lib/python3.13/site-packages/telegram/ext/_updater.py", line 376, in polling_action_cb
  File "/Users/admin/tears/code/.venv/lib/python3.13/site-packages/telegram/ext/_extbot.py", line 658, in get_updates
  File "/Users/admin/tears/code/.venv/lib/python3.13/site-packages/telegram/_bot.py", line 4605, in get_updates
  File "/Users/admin/tears/code/.venv/lib/python3.13/site-packages/telegram/_bot.py", line 691, in _post
  File "/Users/admin/tears/code/.venv/lib/python3.13/site-packages/telegram/ext/_extbot.py", line 362, in _do_post
  File "/Users/admin/tears/code/.venv/lib/python3.13/site-packages/telegram/_bot.py", line 720, in _do_post
  File "/Users/admin/tears/code/.venv/lib/python3.13/site-packages/telegram/request/_baserequest.py", line 202, in post
  File "/Users/admin/tears/code/.venv/lib/python3.13/site-packages/telegram/request/_baserequest.py", line 385, in _request_wrapper
telegram.error.Conflict: Conflict: terminated by other getUpdates request; make sure that only one bot instance is running
No error handlers are registered, logging exception.
Traceback (most recent call last):
  File "/Users/admin/tears/code/.venv/lib/python3.13/site-packages/telegram/ext/_utils/networkloop.py", line 115, in network_retry_loop
  File "/Users/admin/tears/code/.venv/lib/python3.13/site-packages/telegram/ext/_utils/networkloop.py", line 108, in do_action
  File "/Users/admin/tears/code/.venv/lib/python3.13/site-packages/telegram/ext/_updater.py", line 376, in polling_action_cb
  File "/Users/admin/tears/code/.venv/lib/python3.13/site-packages/telegram/ext/_extbot.py", line 658, in get_updates
  File "/Users/admin/tears/code/.venv/lib/python3.13/site-packages/telegram/_bot.py", line 4605, in get_updates
  File "/Users/admin/tears/code/.venv/lib/python3.13/site-packages/telegram/_bot.py", line 691, in _post
  File "/Users/admin/tears/code/.venv/lib/python3.13/site-packages/telegram/ext/_extbot.py", line 362, in _do_post
  File "/Users/admin/tears/code/.venv/lib/python3.13/site-packages/telegram/_bot.py", line 720, in _do_post
  File "/Users/admin/tears/code/.venv/lib/python3.13/site-packages/telegram/request/_baserequest.py", line 202, in post
  File "/Users/admin/tears/code/.venv/lib/python3.13/site-packages/telegram/request/_baserequest.py", line 385, in _request_wrapper
telegram.error.Conflict: Conflict: terminated by other getUpdates request; make sure that only one bot instance is running
